package com.connorwojtak.world.gen;

import java.util.Random;

import javax.annotation.Nullable;

import com.connorwojtak.common.OreGalore;

import net.minecraft.block.Block;
import net.minecraft.block.BlockChest;
import net.minecraft.block.BlockDispenser;
import net.minecraft.block.state.IBlockState;
import net.minecraft.client.Minecraft;
import net.minecraft.entity.Entity;
import net.minecraft.init.Blocks;
import net.minecraft.init.Items;
import net.minecraft.init.PotionTypes;
import net.minecraft.item.ItemArrow;
import net.minecraft.item.ItemStack;
import net.minecraft.item.ItemTippedArrow;
import net.minecraft.nbt.NBTTagCompound;
import net.minecraft.potion.PotionEffect;
import net.minecraft.potion.PotionUtils;
import net.minecraft.tileentity.TileEntity;
import net.minecraft.tileentity.TileEntityChest;
import net.minecraft.tileentity.TileEntityDispenser;
import net.minecraft.util.DamageSource;
import net.minecraft.util.EnumFacing;
import net.minecraft.util.ResourceLocation;
import net.minecraft.util.math.BlockPos;
import net.minecraft.world.World;
import net.minecraft.world.WorldServer;
import net.minecraft.world.chunk.IChunkGenerator;
import net.minecraft.world.chunk.IChunkProvider;
import net.minecraft.world.gen.feature.WorldGenerator;
import net.minecraft.world.gen.structure.MapGenStructureIO;
import net.minecraft.world.gen.structure.StructureBoundingBox;
import net.minecraft.world.gen.structure.StructureComponent;
import net.minecraft.world.gen.structure.template.TemplateManager;
import net.minecraft.world.storage.loot.LootContext;
import net.minecraft.world.storage.loot.LootTable;
import net.minecraftforge.common.DimensionManager;
import net.minecraftforge.fml.common.IWorldGenerator;

public class ComponentHumanStrongholdStructure
{
	public ComponentHumanStrongholdStructure() { }
	
	public static void setBlock(World world, int x, int y, int z, Block block, int metadata)
	{
		Block b1 = world.getBlockState(new BlockPos(x, y, z)).getBlock();

		if(b1 == Blocks.AIR || b1 == Blocks.LEAVES)
		{
			world.setBlockState(new BlockPos(x, y, z), block.getDefaultState());
		}
	}
	
	public static class Stronghold extends StructureComponent
	{
		int scatteredFeatureSizeX;
		int scatteredFeatureSizeY;
		int scatteredFeatureSizeZ;
		int horizontalPos;
		
	protected static Block[] getValidSpawnBlocks() {
		return new Block[] {
			Blocks.STONE,
			Blocks.SAND,
			Blocks.GRASS,
			Blocks.DIRT,
			Blocks.COBBLESTONE,
			Blocks.MOSSY_COBBLESTONE,
			Blocks.NETHERRACK
		};
	}

	public Stronghold(){
		
	}
	
	public Stronghold(Random rand, int x, int y, int z, int sizeX, int sizeY, int sizeZ) {
		super(0);
        this.scatteredFeatureSizeX = sizeX;
        this.scatteredFeatureSizeY = sizeY;
        this.scatteredFeatureSizeZ = sizeZ;
        this.setCoordBaseMode(EnumFacing.Plane.HORIZONTAL.random(rand));
        if (this.getCoordBaseMode().getAxis() == EnumFacing.Axis.Z)
        {
            this.boundingBox = new StructureBoundingBox(x, y, z, x + sizeX - 1, y + sizeY - 1, z + sizeZ - 1);
        }
        else
        {
            this.boundingBox = new StructureBoundingBox(x, y, z, x + sizeZ - 1, y + sizeY - 1, z + sizeX - 1);
        }
	}

	protected void replaceBlocksDownwards(World worldIn, int x, int y, int z)
    {
		int a;
		int b;
		int c;
		for(a = 0; a <= 25; a++){
			for(b = 0; b <= 16; b++){
				for(c = 0; c <= 15; c++){
					worldIn.setBlockState(new BlockPos(x + c, y - a, z + b), Blocks.STONE.getDefaultState());
				}
			}
		}
    }
	
	protected boolean func_191080_ab(World p_191080_1_, StructureBoundingBox p_191080_2_, Random p_191080_3_, BlockPos p_191080_4_, ResourceLocation p_191080_5_, @Nullable IBlockState p_191080_6_, EnumFacing facing)
    {
		if (p_191080_6_ == null){
			p_191080_6_ = Blocks.CHEST.correctFacing(p_191080_1_, p_191080_4_, Blocks.CHEST.getDefaultState());
        }

            p_191080_1_.setBlockState(p_191080_4_, p_191080_6_, 2);
            TileEntity tileentity = p_191080_1_.getTileEntity(p_191080_4_);
            if(facing != null) { p_191080_1_.getBlockState(p_191080_4_).getBlock().rotateBlock(p_191080_1_, p_191080_4_, facing); }
            
       if (tileentity instanceof TileEntityChest){
           ((TileEntityChest)tileentity).setLootTable(p_191080_5_, p_191080_3_.nextLong());
       }
       return true;
    }
	
	protected boolean generateADispenser(World worldIn, StructureBoundingBox structurebb, Random randomIn, int x, int y, int z)
    {
        BlockPos blockpos = new BlockPos(x, y, z);
        return this.func_191080_ac(worldIn, structurebb, randomIn, blockpos, Blocks.DISPENSER.getDefaultState());
    }
	
	
	protected boolean func_191080_ac(World p_191080_1_, StructureBoundingBox p_191080_2_, Random p_191080_3_, BlockPos p_191080_4_, @Nullable IBlockState p_191080_6_)
    {
		if (p_191080_6_ == null){
			p_191080_6_ = Blocks.CHEST.correctFacing(p_191080_1_, p_191080_4_, Blocks.CHEST.getDefaultState());
        }

            p_191080_1_.setBlockState(p_191080_4_, p_191080_6_, 2);
            TileEntity tileentity = p_191080_1_.getTileEntity(p_191080_4_);
            
       if (tileentity instanceof TileEntityDispenser){
           ((TileEntityDispenser)tileentity).addItemStack(new ItemStack(new ItemArrow(), 10));
       }
       return true;
    }
	
	protected boolean generateAChest(World worldIn, StructureBoundingBox structurebb, Random randomIn, int x, int y, int z, ResourceLocation loot, EnumFacing facing)
    {
        BlockPos blockpos = new BlockPos(x, y, z);
        return this.func_191080_ab(worldIn, structurebb, randomIn, blockpos, loot, Blocks.CHEST.getDefaultState(), facing);
    }
	
	public boolean generate(World world, Random rand, StructureBoundingBox structureBoundingBoxIn) {
		//check that each corner is one of the valid spawn blocks
		int i = structureBoundingBoxIn.minX; 
		int j = structureBoundingBoxIn.minY;
		int k = structureBoundingBoxIn.minZ;
		
		k = k - 10;
		j = j + 25;
		i = i - 10;
		
		ComponentHumanStrongholdStructure.setBlock(world, i + 0, j + 0, k + 0, Blocks.STONE, 0);
		ComponentHumanStrongholdStructure.setBlock(world, i + 0, j + 0, k + 1, Blocks.STONE, 0);
		ComponentHumanStrongholdStructure.setBlock(world, i + 0, j + 0, k + 2, Blocks.STONE, 0);
		ComponentHumanStrongholdStructure.setBlock(world, i + 0, j + 0, k + 3, Blocks.STONE, 0);
		ComponentHumanStrongholdStructure.setBlock(world, i + 0, j + 0, k + 4, Blocks.STONE, 0);
		ComponentHumanStrongholdStructure.setBlock(world, i + 0, j + 0, k + 5, Blocks.STONE, 0);
		ComponentHumanStrongholdStructure.setBlock(world, i + 0, j + 0, k + 6, Blocks.STONE, 0);
		ComponentHumanStrongholdStructure.setBlock(world, i + 0, j + 0, k + 7, Blocks.STONE, 0);
		ComponentHumanStrongholdStructure.setBlock(world, i + 0, j + 0, k + 8, Blocks.STONE, 0);
		ComponentHumanStrongholdStructure.setBlock(world, i + 0, j + 0, k + 9, Blocks.STONE, 0);
		ComponentHumanStrongholdStructure.setBlock(world, i + 0, j + 0, k + 10, Blocks.STONE, 0);
		ComponentHumanStrongholdStructure.setBlock(world, i + 0, j + 0, k + 11, Blocks.STONE, 0);
		ComponentHumanStrongholdStructure.setBlock(world, i + 0, j + 0, k + 12, Blocks.STONE, 0);
		ComponentHumanStrongholdStructure.setBlock(world, i + 0, j + 0, k + 13, Blocks.STONE, 0);
		ComponentHumanStrongholdStructure.setBlock(world, i + 0, j + 0, k + 14, Blocks.STONE, 0);
		ComponentHumanStrongholdStructure.setBlock(world, i + 0, j + 0, k + 15, Blocks.STONE, 0);
		ComponentHumanStrongholdStructure.setBlock(world, i + 0, j + 0, k + 16, Blocks.STONE, 0);
		ComponentHumanStrongholdStructure.setBlock(world, i + 0, j + 1, k + 0, Blocks.COBBLESTONE, 0);
		ComponentHumanStrongholdStructure.setBlock(world, i + 0, j + 1, k + 1, Blocks.COBBLESTONE, 0);
		ComponentHumanStrongholdStructure.setBlock(world, i + 0, j + 1, k + 2, Blocks.COBBLESTONE, 0);
		ComponentHumanStrongholdStructure.setBlock(world, i + 0, j + 1, k + 3, Blocks.COBBLESTONE, 0);
		ComponentHumanStrongholdStructure.setBlock(world, i + 0, j + 1, k + 4, Blocks.COBBLESTONE, 0);
		ComponentHumanStrongholdStructure.setBlock(world, i + 0, j + 1, k + 5, Blocks.COBBLESTONE, 0);
		ComponentHumanStrongholdStructure.setBlock(world, i + 0, j + 1, k + 6, Blocks.COBBLESTONE, 0);
		ComponentHumanStrongholdStructure.setBlock(world, i + 0, j + 1, k + 7, Blocks.COBBLESTONE, 0);
		ComponentHumanStrongholdStructure.setBlock(world, i + 0, j + 1, k + 8, Blocks.MOSSY_COBBLESTONE, 0);
		ComponentHumanStrongholdStructure.setBlock(world, i + 0, j + 1, k + 9, Blocks.MOSSY_COBBLESTONE, 0);
		ComponentHumanStrongholdStructure.setBlock(world, i + 0, j + 1, k + 10, Blocks.COBBLESTONE, 0);
		ComponentHumanStrongholdStructure.setBlock(world, i + 0, j + 1, k + 11, Blocks.MOSSY_COBBLESTONE, 0);
		ComponentHumanStrongholdStructure.setBlock(world, i + 0, j + 1, k + 12, Blocks.MOSSY_COBBLESTONE, 0);
		ComponentHumanStrongholdStructure.setBlock(world, i + 0, j + 1, k + 13, Blocks.COBBLESTONE, 0);
		ComponentHumanStrongholdStructure.setBlock(world, i + 0, j + 1, k + 14, Blocks.COBBLESTONE, 0);
		ComponentHumanStrongholdStructure.setBlock(world, i + 0, j + 1, k + 15, Blocks.COBBLESTONE, 0);
		ComponentHumanStrongholdStructure.setBlock(world, i + 0, j + 1, k + 16, Blocks.COBBLESTONE, 0);
		ComponentHumanStrongholdStructure.setBlock(world, i + 0, j + 2, k + 0, Blocks.COBBLESTONE, 0);
		ComponentHumanStrongholdStructure.setBlock(world, i + 0, j + 2, k + 1, Blocks.COBBLESTONE, 0);
		ComponentHumanStrongholdStructure.setBlock(world, i + 0, j + 2, k + 2, Blocks.COBBLESTONE, 0);
		ComponentHumanStrongholdStructure.setBlock(world, i + 0, j + 2, k + 3, Blocks.MOSSY_COBBLESTONE, 0);
		ComponentHumanStrongholdStructure.setBlock(world, i + 0, j + 2, k + 4, Blocks.COBBLESTONE, 0);
		ComponentHumanStrongholdStructure.setBlock(world, i + 0, j + 2, k + 5, Blocks.COBBLESTONE, 0);
		ComponentHumanStrongholdStructure.setBlock(world, i + 0, j + 2, k + 6, Blocks.COBBLESTONE, 0);
		ComponentHumanStrongholdStructure.setBlock(world, i + 0, j + 2, k + 7, Blocks.COBBLESTONE, 0);
		ComponentHumanStrongholdStructure.setBlock(world, i + 0, j + 2, k + 8, Blocks.COBBLESTONE, 0);
		ComponentHumanStrongholdStructure.setBlock(world, i + 0, j + 2, k + 9, Blocks.MOSSY_COBBLESTONE, 0);
		ComponentHumanStrongholdStructure.setBlock(world, i + 0, j + 2, k + 10, Blocks.COBBLESTONE, 0);
		ComponentHumanStrongholdStructure.setBlock(world, i + 0, j + 2, k + 11, Blocks.COBBLESTONE, 0);
		ComponentHumanStrongholdStructure.setBlock(world, i + 0, j + 2, k + 12, Blocks.COBBLESTONE, 0);
		ComponentHumanStrongholdStructure.setBlock(world, i + 0, j + 2, k + 13, Blocks.COBBLESTONE, 0);
		ComponentHumanStrongholdStructure.setBlock(world, i + 0, j + 2, k + 14, Blocks.COBBLESTONE, 0);
		ComponentHumanStrongholdStructure.setBlock(world, i + 0, j + 2, k + 15, Blocks.COBBLESTONE, 0);
		ComponentHumanStrongholdStructure.setBlock(world, i + 0, j + 2, k + 16, Blocks.COBBLESTONE, 0);
		ComponentHumanStrongholdStructure.setBlock(world, i + 0, j + 3, k + 0, Blocks.COBBLESTONE, 0);
		ComponentHumanStrongholdStructure.setBlock(world, i + 0, j + 3, k + 1, Blocks.COBBLESTONE, 0);
		ComponentHumanStrongholdStructure.setBlock(world, i + 0, j + 3, k + 2, Blocks.COBBLESTONE, 0);
		ComponentHumanStrongholdStructure.setBlock(world, i + 0, j + 3, k + 3, Blocks.COBBLESTONE, 0);
		ComponentHumanStrongholdStructure.setBlock(world, i + 0, j + 3, k + 4, Blocks.COBBLESTONE, 0);
		ComponentHumanStrongholdStructure.setBlock(world, i + 0, j + 3, k + 5, Blocks.COBBLESTONE, 0);
		ComponentHumanStrongholdStructure.setBlock(world, i + 0, j + 3, k + 6, Blocks.COBBLESTONE, 0);
		ComponentHumanStrongholdStructure.setBlock(world, i + 0, j + 3, k + 7, Blocks.COBBLESTONE, 0);
		ComponentHumanStrongholdStructure.setBlock(world, i + 0, j + 3, k + 8, Blocks.COBBLESTONE, 0);
		ComponentHumanStrongholdStructure.setBlock(world, i + 0, j + 3, k + 9, Blocks.COBBLESTONE, 0);
		ComponentHumanStrongholdStructure.setBlock(world, i + 0, j + 3, k + 10, Blocks.COBBLESTONE, 0);
		ComponentHumanStrongholdStructure.setBlock(world, i + 0, j + 3, k + 11, Blocks.COBBLESTONE, 0);
		ComponentHumanStrongholdStructure.setBlock(world, i + 0, j + 3, k + 12, Blocks.COBBLESTONE, 0);
		ComponentHumanStrongholdStructure.setBlock(world, i + 0, j + 3, k + 13, Blocks.MOSSY_COBBLESTONE, 0);
		ComponentHumanStrongholdStructure.setBlock(world, i + 0, j + 3, k + 14, Blocks.COBBLESTONE, 0);
		ComponentHumanStrongholdStructure.setBlock(world, i + 0, j + 3, k + 15, Blocks.COBBLESTONE, 0);
		ComponentHumanStrongholdStructure.setBlock(world, i + 0, j + 3, k + 16, Blocks.COBBLESTONE, 0);
		ComponentHumanStrongholdStructure.setBlock(world, i + 0, j + 4, k + 0, Blocks.COBBLESTONE, 0);
		ComponentHumanStrongholdStructure.setBlock(world, i + 0, j + 4, k + 1, Blocks.COBBLESTONE, 0);
		ComponentHumanStrongholdStructure.setBlock(world, i + 0, j + 4, k + 2, Blocks.COBBLESTONE, 0);
		ComponentHumanStrongholdStructure.setBlock(world, i + 0, j + 4, k + 3, Blocks.COBBLESTONE, 0);
		ComponentHumanStrongholdStructure.setBlock(world, i + 0, j + 4, k + 4, Blocks.MOSSY_COBBLESTONE, 0);
		ComponentHumanStrongholdStructure.setBlock(world, i + 0, j + 4, k + 5, Blocks.MOSSY_COBBLESTONE, 0);
		ComponentHumanStrongholdStructure.setBlock(world, i + 0, j + 4, k + 6, Blocks.COBBLESTONE, 0);
		ComponentHumanStrongholdStructure.setBlock(world, i + 0, j + 4, k + 7, Blocks.MOSSY_COBBLESTONE, 0);
		ComponentHumanStrongholdStructure.setBlock(world, i + 0, j + 4, k + 8, Blocks.MOSSY_COBBLESTONE, 0);
		ComponentHumanStrongholdStructure.setBlock(world, i + 0, j + 4, k + 9, Blocks.MOSSY_COBBLESTONE, 0);
		ComponentHumanStrongholdStructure.setBlock(world, i + 0, j + 4, k + 10, Blocks.MOSSY_COBBLESTONE, 0);
		ComponentHumanStrongholdStructure.setBlock(world, i + 0, j + 4, k + 11, Blocks.COBBLESTONE, 0);
		ComponentHumanStrongholdStructure.setBlock(world, i + 0, j + 4, k + 12, Blocks.COBBLESTONE, 0);
		ComponentHumanStrongholdStructure.setBlock(world, i + 0, j + 4, k + 13, Blocks.MOSSY_COBBLESTONE, 0);
		ComponentHumanStrongholdStructure.setBlock(world, i + 0, j + 4, k + 14, Blocks.COBBLESTONE, 0);
		ComponentHumanStrongholdStructure.setBlock(world, i + 0, j + 4, k + 15, Blocks.COBBLESTONE, 0);
		ComponentHumanStrongholdStructure.setBlock(world, i + 0, j + 4, k + 16, Blocks.COBBLESTONE, 0);
		ComponentHumanStrongholdStructure.setBlock(world, i + 0, j + 5, k + 0, Blocks.COBBLESTONE, 0);
		ComponentHumanStrongholdStructure.setBlock(world, i + 0, j + 5, k + 1, Blocks.MOSSY_COBBLESTONE, 0);
		ComponentHumanStrongholdStructure.setBlock(world, i + 0, j + 5, k + 2, Blocks.COBBLESTONE, 0);
		ComponentHumanStrongholdStructure.setBlock(world, i + 0, j + 5, k + 3, Blocks.COBBLESTONE, 0);
		ComponentHumanStrongholdStructure.setBlock(world, i + 0, j + 5, k + 4, Blocks.COBBLESTONE, 0);
		ComponentHumanStrongholdStructure.setBlock(world, i + 0, j + 5, k + 5, Blocks.COBBLESTONE, 0);
		ComponentHumanStrongholdStructure.setBlock(world, i + 0, j + 5, k + 6, Blocks.COBBLESTONE, 0);
		ComponentHumanStrongholdStructure.setBlock(world, i + 0, j + 5, k + 7, Blocks.COBBLESTONE, 0);
		ComponentHumanStrongholdStructure.setBlock(world, i + 0, j + 5, k + 8, Blocks.COBBLESTONE, 0);
		ComponentHumanStrongholdStructure.setBlock(world, i + 0, j + 5, k + 9, Blocks.COBBLESTONE, 0);
		ComponentHumanStrongholdStructure.setBlock(world, i + 0, j + 5, k + 10, Blocks.COBBLESTONE, 0);
		ComponentHumanStrongholdStructure.setBlock(world, i + 0, j + 5, k + 11, Blocks.COBBLESTONE, 0);
		ComponentHumanStrongholdStructure.setBlock(world, i + 0, j + 5, k + 12, Blocks.COBBLESTONE, 0);
		ComponentHumanStrongholdStructure.setBlock(world, i + 0, j + 5, k + 13, Blocks.COBBLESTONE, 0);
		ComponentHumanStrongholdStructure.setBlock(world, i + 0, j + 5, k + 14, Blocks.COBBLESTONE, 0);
		ComponentHumanStrongholdStructure.setBlock(world, i + 0, j + 5, k + 15, Blocks.MOSSY_COBBLESTONE, 0);
		ComponentHumanStrongholdStructure.setBlock(world, i + 0, j + 5, k + 16, Blocks.COBBLESTONE, 0);
		ComponentHumanStrongholdStructure.setBlock(world, i + 0, j + 6, k + 0, Blocks.COBBLESTONE, 0);
		ComponentHumanStrongholdStructure.setBlock(world, i + 0, j + 6, k + 1, Blocks.COBBLESTONE, 0);
		ComponentHumanStrongholdStructure.setBlock(world, i + 0, j + 6, k + 2, Blocks.COBBLESTONE, 0);
		ComponentHumanStrongholdStructure.setBlock(world, i + 0, j + 6, k + 3, Blocks.MOSSY_COBBLESTONE, 0);
		ComponentHumanStrongholdStructure.setBlock(world, i + 0, j + 6, k + 4, Blocks.COBBLESTONE, 0);
		ComponentHumanStrongholdStructure.setBlock(world, i + 0, j + 6, k + 5, Blocks.COBBLESTONE, 0);
		ComponentHumanStrongholdStructure.setBlock(world, i + 0, j + 6, k + 6, Blocks.COBBLESTONE, 0);
		ComponentHumanStrongholdStructure.setBlock(world, i + 0, j + 6, k + 7, Blocks.COBBLESTONE, 0);
		ComponentHumanStrongholdStructure.setBlock(world, i + 0, j + 6, k + 8, Blocks.COBBLESTONE, 0);
		ComponentHumanStrongholdStructure.setBlock(world, i + 0, j + 6, k + 9, Blocks.COBBLESTONE, 0);
		ComponentHumanStrongholdStructure.setBlock(world, i + 0, j + 6, k + 10, Blocks.COBBLESTONE, 0);
		ComponentHumanStrongholdStructure.setBlock(world, i + 0, j + 6, k + 11, Blocks.MOSSY_COBBLESTONE, 0);
		ComponentHumanStrongholdStructure.setBlock(world, i + 0, j + 6, k + 12, Blocks.COBBLESTONE, 0);
		ComponentHumanStrongholdStructure.setBlock(world, i + 0, j + 6, k + 13, Blocks.MOSSY_COBBLESTONE, 0);
		ComponentHumanStrongholdStructure.setBlock(world, i + 0, j + 6, k + 14, Blocks.COBBLESTONE, 0);
		ComponentHumanStrongholdStructure.setBlock(world, i + 0, j + 6, k + 15, Blocks.COBBLESTONE, 0);
		ComponentHumanStrongholdStructure.setBlock(world, i + 0, j + 6, k + 16, Blocks.COBBLESTONE, 0);
		ComponentHumanStrongholdStructure.setBlock(world, i + 0, j + 7, k + 0, Blocks.COBBLESTONE, 0);
		ComponentHumanStrongholdStructure.setBlock(world, i + 0, j + 7, k + 1, Blocks.COBBLESTONE, 0);
		ComponentHumanStrongholdStructure.setBlock(world, i + 0, j + 7, k + 2, Blocks.MOSSY_COBBLESTONE, 0);
		ComponentHumanStrongholdStructure.setBlock(world, i + 0, j + 7, k + 3, Blocks.COBBLESTONE, 0);
		ComponentHumanStrongholdStructure.setBlock(world, i + 0, j + 7, k + 4, Blocks.MOSSY_COBBLESTONE, 0);
		ComponentHumanStrongholdStructure.setBlock(world, i + 0, j + 7, k + 5, Blocks.COBBLESTONE, 0);
		ComponentHumanStrongholdStructure.setBlock(world, i + 0, j + 7, k + 6, Blocks.COBBLESTONE, 0);
		ComponentHumanStrongholdStructure.setBlock(world, i + 0, j + 7, k + 7, Blocks.MOSSY_COBBLESTONE, 0);
		ComponentHumanStrongholdStructure.setBlock(world, i + 0, j + 7, k + 8, Blocks.COBBLESTONE, 0);
		ComponentHumanStrongholdStructure.setBlock(world, i + 0, j + 7, k + 9, Blocks.MOSSY_COBBLESTONE, 0);
		ComponentHumanStrongholdStructure.setBlock(world, i + 0, j + 7, k + 10, Blocks.COBBLESTONE, 0);
		ComponentHumanStrongholdStructure.setBlock(world, i + 0, j + 7, k + 11, Blocks.COBBLESTONE, 0);
		ComponentHumanStrongholdStructure.setBlock(world, i + 0, j + 7, k + 12, Blocks.MOSSY_COBBLESTONE, 0);
		ComponentHumanStrongholdStructure.setBlock(world, i + 0, j + 7, k + 13, Blocks.COBBLESTONE, 0);
		ComponentHumanStrongholdStructure.setBlock(world, i + 0, j + 7, k + 14, Blocks.COBBLESTONE, 0);
		ComponentHumanStrongholdStructure.setBlock(world, i + 0, j + 7, k + 15, Blocks.MOSSY_COBBLESTONE, 0);
		ComponentHumanStrongholdStructure.setBlock(world, i + 0, j + 7, k + 16, Blocks.COBBLESTONE, 0);
		ComponentHumanStrongholdStructure.setBlock(world, i + 0, j + 8, k + 0, Blocks.COBBLESTONE, 0);
		ComponentHumanStrongholdStructure.setBlock(world, i + 0, j + 8, k + 1, Blocks.COBBLESTONE, 0);
		ComponentHumanStrongholdStructure.setBlock(world, i + 0, j + 8, k + 2, Blocks.COBBLESTONE, 0);
		ComponentHumanStrongholdStructure.setBlock(world, i + 0, j + 8, k + 3, Blocks.COBBLESTONE, 0);
		ComponentHumanStrongholdStructure.setBlock(world, i + 0, j + 8, k + 4, Blocks.MOSSY_COBBLESTONE, 0);
		ComponentHumanStrongholdStructure.setBlock(world, i + 0, j + 8, k + 5, Blocks.MOSSY_COBBLESTONE, 0);
		ComponentHumanStrongholdStructure.setBlock(world, i + 0, j + 8, k + 6, Blocks.COBBLESTONE, 0);
		ComponentHumanStrongholdStructure.setBlock(world, i + 0, j + 8, k + 7, Blocks.COBBLESTONE, 0);
		ComponentHumanStrongholdStructure.setBlock(world, i + 0, j + 8, k + 8, Blocks.MOSSY_COBBLESTONE, 0);
		ComponentHumanStrongholdStructure.setBlock(world, i + 0, j + 8, k + 9, Blocks.COBBLESTONE, 0);
		ComponentHumanStrongholdStructure.setBlock(world, i + 0, j + 8, k + 10, Blocks.MOSSY_COBBLESTONE, 0);
		ComponentHumanStrongholdStructure.setBlock(world, i + 0, j + 8, k + 11, Blocks.COBBLESTONE, 0);
		ComponentHumanStrongholdStructure.setBlock(world, i + 0, j + 8, k + 12, Blocks.COBBLESTONE, 0);
		ComponentHumanStrongholdStructure.setBlock(world, i + 0, j + 8, k + 13, Blocks.STONEBRICK, 1);
		ComponentHumanStrongholdStructure.setBlock(world, i + 0, j + 8, k + 14, Blocks.MOSSY_COBBLESTONE, 0);
		ComponentHumanStrongholdStructure.setBlock(world, i + 0, j + 8, k + 15, Blocks.COBBLESTONE, 0);
		ComponentHumanStrongholdStructure.setBlock(world, i + 0, j + 8, k + 16, Blocks.COBBLESTONE, 0);
		ComponentHumanStrongholdStructure.setBlock(world, i + 0, j + 9, k + 0, Blocks.COBBLESTONE, 0);
		ComponentHumanStrongholdStructure.setBlock(world, i + 0, j + 9, k + 1, Blocks.COBBLESTONE, 0);
		ComponentHumanStrongholdStructure.setBlock(world, i + 0, j + 9, k + 2, Blocks.MOSSY_COBBLESTONE, 0);
		ComponentHumanStrongholdStructure.setBlock(world, i + 0, j + 9, k + 3, Blocks.COBBLESTONE, 0);
		ComponentHumanStrongholdStructure.setBlock(world, i + 0, j + 9, k + 4, Blocks.COBBLESTONE, 0);
		ComponentHumanStrongholdStructure.setBlock(world, i + 0, j + 9, k + 5, Blocks.COBBLESTONE, 0);
		ComponentHumanStrongholdStructure.setBlock(world, i + 0, j + 9, k + 6, Blocks.COBBLESTONE, 0);
		ComponentHumanStrongholdStructure.setBlock(world, i + 0, j + 9, k + 7, Blocks.COBBLESTONE, 0);
		ComponentHumanStrongholdStructure.setBlock(world, i + 0, j + 9, k + 8, Blocks.COBBLESTONE, 0);
		ComponentHumanStrongholdStructure.setBlock(world, i + 0, j + 9, k + 9, Blocks.COBBLESTONE, 0);
		ComponentHumanStrongholdStructure.setBlock(world, i + 0, j + 9, k + 10, Blocks.COBBLESTONE, 0);
		ComponentHumanStrongholdStructure.setBlock(world, i + 0, j + 9, k + 11, Blocks.COBBLESTONE, 0);
		ComponentHumanStrongholdStructure.setBlock(world, i + 0, j + 9, k + 12, Blocks.COBBLESTONE, 0);
		ComponentHumanStrongholdStructure.setBlock(world, i + 0, j + 9, k + 13, Blocks.COBBLESTONE, 0);
		ComponentHumanStrongholdStructure.setBlock(world, i + 0, j + 9, k + 14, Blocks.STONEBRICK, 2);
		ComponentHumanStrongholdStructure.setBlock(world, i + 0, j + 9, k + 15, Blocks.STONEBRICK, 1);
		ComponentHumanStrongholdStructure.setBlock(world, i + 0, j + 10, k + 0, Blocks.COBBLESTONE, 0);
		ComponentHumanStrongholdStructure.setBlock(world, i + 0, j + 10, k + 1, Blocks.COBBLESTONE, 0);
		ComponentHumanStrongholdStructure.setBlock(world, i + 0, j + 10, k + 2, Blocks.COBBLESTONE, 0);
		ComponentHumanStrongholdStructure.setBlock(world, i + 0, j + 10, k + 3, Blocks.COBBLESTONE, 0);
		ComponentHumanStrongholdStructure.setBlock(world, i + 0, j + 10, k + 4, Blocks.COBBLESTONE, 0);
		ComponentHumanStrongholdStructure.setBlock(world, i + 0, j + 10, k + 5, Blocks.COBBLESTONE, 0);
		ComponentHumanStrongholdStructure.setBlock(world, i + 0, j + 10, k + 6, Blocks.COBBLESTONE, 0);
		ComponentHumanStrongholdStructure.setBlock(world, i + 0, j + 10, k + 7, Blocks.COBBLESTONE, 0);
		ComponentHumanStrongholdStructure.setBlock(world, i + 0, j + 10, k + 8, Blocks.COBBLESTONE, 0);
		ComponentHumanStrongholdStructure.setBlock(world, i + 0, j + 10, k + 9, Blocks.COBBLESTONE, 0);
		ComponentHumanStrongholdStructure.setBlock(world, i + 0, j + 10, k + 10, Blocks.COBBLESTONE, 0);
		ComponentHumanStrongholdStructure.setBlock(world, i + 0, j + 10, k + 11, Blocks.COBBLESTONE, 0);
		ComponentHumanStrongholdStructure.setBlock(world, i + 0, j + 10, k + 12, Blocks.COBBLESTONE, 0);
		ComponentHumanStrongholdStructure.setBlock(world, i + 0, j + 10, k + 13, Blocks.COBBLESTONE, 0);
		ComponentHumanStrongholdStructure.setBlock(world, i + 0, j + 10, k + 14, Blocks.COBBLESTONE, 0);
		ComponentHumanStrongholdStructure.setBlock(world, i + 0, j + 10, k + 15, Blocks.COBBLESTONE, 0);
		ComponentHumanStrongholdStructure.setBlock(world, i + 0, j + 11, k + 1, Blocks.STONEBRICK, 2);
		ComponentHumanStrongholdStructure.setBlock(world, i + 0, j + 11, k + 2, Blocks.STONEBRICK, 1);
		ComponentHumanStrongholdStructure.setBlock(world, i + 0, j + 11, k + 4, Blocks.STONEBRICK, 0);
		ComponentHumanStrongholdStructure.setBlock(world, i + 0, j + 11, k + 5, Blocks.STONEBRICK, 0);
		ComponentHumanStrongholdStructure.setBlock(world, i + 0, j + 11, k + 7, Blocks.MOSSY_COBBLESTONE, 0);
		ComponentHumanStrongholdStructure.setBlock(world, i + 0, j + 11, k + 8, Blocks.COBBLESTONE, 0);
		ComponentHumanStrongholdStructure.setBlock(world, i + 0, j + 11, k + 10, Blocks.STONEBRICK, 0);
		ComponentHumanStrongholdStructure.setBlock(world, i + 0, j + 11, k + 11, Blocks.STONEBRICK, 0);
		ComponentHumanStrongholdStructure.setBlock(world, i + 0, j + 11, k + 13, Blocks.STONEBRICK, 1);
		ComponentHumanStrongholdStructure.setBlock(world, i + 0, j + 11, k + 14, Blocks.STONEBRICK, 0);
		ComponentHumanStrongholdStructure.setBlock(world, i + 0, j + 12, k + 1, Blocks.STONEBRICK, 1);
		ComponentHumanStrongholdStructure.setBlock(world, i + 0, j + 12, k + 8, Blocks.COBBLESTONE, 0);
		ComponentHumanStrongholdStructure.setBlock(world, i + 0, j + 12, k + 10, Blocks.STONEBRICK, 1);
		ComponentHumanStrongholdStructure.setBlock(world, i + 0, j + 12, k + 11, Blocks.STONEBRICK, 1);
		ComponentHumanStrongholdStructure.setBlock(world, i + 0, j + 12, k + 13, Blocks.STONEBRICK, 1);
		ComponentHumanStrongholdStructure.setBlock(world, i + 0, j + 12, k + 14, Blocks.STONEBRICK, 0);
		ComponentHumanStrongholdStructure.setBlock(world, i + 1, j + 0, k + 0, Blocks.STONE, 0);
		ComponentHumanStrongholdStructure.setBlock(world, i + 1, j + 0, k + 1, Blocks.STONE, 0);
		ComponentHumanStrongholdStructure.setBlock(world, i + 1, j + 0, k + 2, Blocks.STONE, 0);
		ComponentHumanStrongholdStructure.setBlock(world, i + 1, j + 0, k + 3, Blocks.STONE, 0);
		ComponentHumanStrongholdStructure.setBlock(world, i + 1, j + 0, k + 4, Blocks.STONE, 0);
		ComponentHumanStrongholdStructure.setBlock(world, i + 1, j + 0, k + 5, Blocks.STONE, 0);
		ComponentHumanStrongholdStructure.setBlock(world, i + 1, j + 0, k + 6, Blocks.STONE, 0);
		ComponentHumanStrongholdStructure.setBlock(world, i + 1, j + 0, k + 7, Blocks.COBBLESTONE, 0);
		ComponentHumanStrongholdStructure.setBlock(world, i + 1, j + 0, k + 8, Blocks.COBBLESTONE, 0);
		ComponentHumanStrongholdStructure.setBlock(world, i + 1, j + 0, k + 9, Blocks.COBBLESTONE, 0);
		ComponentHumanStrongholdStructure.setBlock(world, i + 1, j + 0, k + 10, Blocks.COBBLESTONE, 0);
		ComponentHumanStrongholdStructure.setBlock(world, i + 1, j + 0, k + 11, Blocks.COBBLESTONE, 0);
		ComponentHumanStrongholdStructure.setBlock(world, i + 1, j + 0, k + 12, Blocks.COBBLESTONE, 0);
		ComponentHumanStrongholdStructure.setBlock(world, i + 1, j + 0, k + 13, Blocks.COBBLESTONE, 0);
		ComponentHumanStrongholdStructure.setBlock(world, i + 1, j + 0, k + 14, Blocks.COBBLESTONE, 0);
		ComponentHumanStrongholdStructure.setBlock(world, i + 1, j + 0, k + 15, Blocks.COBBLESTONE, 0);
		ComponentHumanStrongholdStructure.setBlock(world, i + 1, j + 0, k + 16, Blocks.STONE, 0);
		ComponentHumanStrongholdStructure.setBlock(world, i + 1, j + 1, k + 0, Blocks.COBBLESTONE, 0);
		ComponentHumanStrongholdStructure.setBlock(world, i + 1, j + 1, k + 7, Blocks.STONEBRICK, 0);
		ComponentHumanStrongholdStructure.setBlock(world, i + 1, j + 1, k + 8, Blocks.STONEBRICK, 0);
		ComponentHumanStrongholdStructure.setBlock(world, i + 1, j + 1, k + 12, Blocks.STONEBRICK, 1);
		ComponentHumanStrongholdStructure.setBlock(world, i + 1, j + 1, k + 13, Blocks.STONEBRICK, 1);
		ComponentHumanStrongholdStructure.setBlock(world, i + 1, j + 1, k + 16, Blocks.COBBLESTONE, 0);
		ComponentHumanStrongholdStructure.setBlock(world, i + 1, j + 2, k + 0, Blocks.COBBLESTONE, 0);
		ComponentHumanStrongholdStructure.setBlock(world, i + 1, j + 2, k + 7, Blocks.STONEBRICK, 0);
		ComponentHumanStrongholdStructure.setBlock(world, i + 1, j + 2, k + 8, Blocks.STONEBRICK, 0);
		ComponentHumanStrongholdStructure.setBlock(world, i + 1, j + 2, k + 12, Blocks.STONEBRICK, 1);
		ComponentHumanStrongholdStructure.setBlock(world, i + 1, j + 2, k + 13, Blocks.STONEBRICK, 1);
		ComponentHumanStrongholdStructure.setBlock(world, i + 1, j + 2, k + 14, Blocks.STONEBRICK, 1);
		ComponentHumanStrongholdStructure.setBlock(world, i + 1, j + 2, k + 16, Blocks.COBBLESTONE, 0);
		ComponentHumanStrongholdStructure.setBlock(world, i + 1, j + 3, k + 0, Blocks.COBBLESTONE, 0);
		ComponentHumanStrongholdStructure.setBlock(world, i + 1, j + 3, k + 7, Blocks.STONEBRICK, 1);
		ComponentHumanStrongholdStructure.setBlock(world, i + 1, j + 3, k + 8, Blocks.STONEBRICK, 2);
		ComponentHumanStrongholdStructure.setBlock(world, i + 1, j + 3, k + 11, Blocks.STONE_BRICK_STAIRS, 5);
		ComponentHumanStrongholdStructure.setBlock(world, i + 1, j + 3, k + 12, Blocks.STONEBRICK, 2);
		ComponentHumanStrongholdStructure.setBlock(world, i + 1, j + 3, k + 13, Blocks.STONEBRICK, 1);
		ComponentHumanStrongholdStructure.setBlock(world, i + 1, j + 3, k + 16, Blocks.COBBLESTONE, 0);
		ComponentHumanStrongholdStructure.setBlock(world, i + 1, j + 4, k + 0, Blocks.COBBLESTONE, 0);
		ComponentHumanStrongholdStructure.setBlock(world, i + 1, j + 4, k + 1, Blocks.STONEBRICK, 2);
		ComponentHumanStrongholdStructure.setBlock(world, i + 1, j + 4, k + 2, Blocks.STONEBRICK, 2);
		ComponentHumanStrongholdStructure.setBlock(world, i + 1, j + 4, k + 3, Blocks.MOSSY_COBBLESTONE, 0);
		ComponentHumanStrongholdStructure.setBlock(world, i + 1, j + 4, k + 4, Blocks.STONEBRICK, 2);
		ComponentHumanStrongholdStructure.setBlock(world, i + 1, j + 4, k + 5, Blocks.STONEBRICK, 2);
		ComponentHumanStrongholdStructure.setBlock(world, i + 1, j + 4, k + 6, Blocks.COBBLESTONE, 0);
		ComponentHumanStrongholdStructure.setBlock(world, i + 1, j + 4, k + 9, Blocks.MOSSY_COBBLESTONE, 0);
		ComponentHumanStrongholdStructure.setBlock(world, i + 1, j + 4, k + 10, Blocks.STONEBRICK, 2);
		ComponentHumanStrongholdStructure.setBlock(world, i + 1, j + 4, k + 11, Blocks.MOSSY_COBBLESTONE, 0);
		ComponentHumanStrongholdStructure.setBlock(world, i + 1, j + 4, k + 12, Blocks.STONEBRICK, 2);
		ComponentHumanStrongholdStructure.setBlock(world, i + 1, j + 4, k + 13, Blocks.STONE, 0);
		ComponentHumanStrongholdStructure.setBlock(world, i + 1, j + 4, k + 14, Blocks.STONE, 0);
		ComponentHumanStrongholdStructure.setBlock(world, i + 1, j + 4, k + 15, Blocks.STONE, 0);
		ComponentHumanStrongholdStructure.setBlock(world, i + 1, j + 4, k + 16, Blocks.COBBLESTONE, 0);
		ComponentHumanStrongholdStructure.setBlock(world, i + 1, j + 5, k + 0, Blocks.COBBLESTONE, 0);
		ComponentHumanStrongholdStructure.setBlock(world, i + 1, j + 5, k + 9, Blocks.STONEBRICK, 0);
		ComponentHumanStrongholdStructure.setBlock(world, i + 1, j + 5, k + 12, Blocks.IRON_BARS, 0);
		ComponentHumanStrongholdStructure.setBlock(world, i + 1, j + 5, k + 13, Blocks.STONE_SLAB2, 5);
		ComponentHumanStrongholdStructure.setBlock(world, i + 1, j + 5, k + 14, Blocks.STONE_SLAB, 5);
		ComponentHumanStrongholdStructure.setBlock(world, i + 1, j + 5, k + 15, Blocks.STONE_SLAB2, 5);
		ComponentHumanStrongholdStructure.setBlock(world, i + 1, j + 5, k + 16, Blocks.COBBLESTONE, 0);
		ComponentHumanStrongholdStructure.setBlock(world, i + 1, j + 6, k + 0, Blocks.COBBLESTONE, 0);
		ComponentHumanStrongholdStructure.setBlock(world, i + 1, j + 6, k + 8, Blocks.STONE_BRICK_STAIRS, 6);
		ComponentHumanStrongholdStructure.setBlock(world, i + 1, j + 6, k + 9, Blocks.STONEBRICK, 1);
		ComponentHumanStrongholdStructure.setBlock(world, i + 1, j + 6, k + 12, Blocks.IRON_BARS, 0);
		ComponentHumanStrongholdStructure.setBlock(world, i + 1, j + 6, k + 16, Blocks.COBBLESTONE, 0);
		ComponentHumanStrongholdStructure.setBlock(world, i + 1, j + 7, k + 0, Blocks.COBBLESTONE, 0);
		ComponentHumanStrongholdStructure.setBlock(world, i + 1, j + 7, k + 8, Blocks.COBBLESTONE, 0);
		ComponentHumanStrongholdStructure.setBlock(world, i + 1, j + 7, k + 10, Blocks.STONEBRICK, 0);
		ComponentHumanStrongholdStructure.setBlock(world, i + 1, j + 7, k + 11, Blocks.STONEBRICK, 1);
		ComponentHumanStrongholdStructure.setBlock(world, i + 1, j + 7, k + 12, Blocks.STONEBRICK, 0);
		ComponentHumanStrongholdStructure.setBlock(world, i + 1, j + 7, k + 13, Blocks.STONEBRICK, 0);
		ComponentHumanStrongholdStructure.setBlock(world, i + 1, j + 7, k + 14, Blocks.MOSSY_COBBLESTONE, 0);
		ComponentHumanStrongholdStructure.setBlock(world, i + 1, j + 7, k + 15, Blocks.MOSSY_COBBLESTONE, 0);
		ComponentHumanStrongholdStructure.setBlock(world, i + 1, j + 7, k + 16, Blocks.COBBLESTONE, 0);
		ComponentHumanStrongholdStructure.setBlock(world, i + 1, j + 8, k + 0, Blocks.COBBLESTONE, 0);
		ComponentHumanStrongholdStructure.setBlock(world, i + 1, j + 8, k + 7, Blocks.COBBLESTONE, 0);
		ComponentHumanStrongholdStructure.setBlock(world, i + 1, j + 8, k + 16, Blocks.COBBLESTONE, 0);
		ComponentHumanStrongholdStructure.setBlock(world, i + 1, j + 9, k + 0, Blocks.COBBLESTONE, 0);
		ComponentHumanStrongholdStructure.setBlock(world, i + 1, j + 9, k + 7, Blocks.MOSSY_COBBLESTONE, 0);
		ComponentHumanStrongholdStructure.setBlock(world, i + 1, j + 9, k + 16, Blocks.COBBLESTONE, 0);
		ComponentHumanStrongholdStructure.setBlock(world, i + 1, j + 10, k + 0, Blocks.COBBLESTONE, 0);
		ComponentHumanStrongholdStructure.setBlock(world, i + 1, j + 10, k + 1, Blocks.COBBLESTONE, 0);
		ComponentHumanStrongholdStructure.setBlock(world, i + 1, j + 10, k + 2, Blocks.COBBLESTONE, 0);
		ComponentHumanStrongholdStructure.setBlock(world, i + 1, j + 10, k + 3, Blocks.COBBLESTONE, 0);
		ComponentHumanStrongholdStructure.setBlock(world, i + 1, j + 10, k + 4, Blocks.COBBLESTONE, 0);
		ComponentHumanStrongholdStructure.setBlock(world, i + 1, j + 10, k + 5, Blocks.COBBLESTONE, 0);
		ComponentHumanStrongholdStructure.setBlock(world, i + 1, j + 10, k + 6, Blocks.COBBLESTONE, 0);
		ComponentHumanStrongholdStructure.setBlock(world, i + 1, j + 10, k + 7, Blocks.MOSSY_COBBLESTONE, 0);
		ComponentHumanStrongholdStructure.setBlock(world, i + 1, j + 10, k + 8, Blocks.COBBLESTONE, 0);
		ComponentHumanStrongholdStructure.setBlock(world, i + 1, j + 10, k + 9, Blocks.COBBLESTONE, 0);
		ComponentHumanStrongholdStructure.setBlock(world, i + 1, j + 10, k + 10, Blocks.COBBLESTONE, 0);
		ComponentHumanStrongholdStructure.setBlock(world, i + 1, j + 10, k + 11, Blocks.COBBLESTONE, 0);
		ComponentHumanStrongholdStructure.setBlock(world, i + 1, j + 10, k + 12, Blocks.COBBLESTONE, 0);
		ComponentHumanStrongholdStructure.setBlock(world, i + 1, j + 10, k + 13, Blocks.COBBLESTONE, 0);
		ComponentHumanStrongholdStructure.setBlock(world, i + 1, j + 10, k + 14, Blocks.COBBLESTONE, 0);
		ComponentHumanStrongholdStructure.setBlock(world, i + 1, j + 10, k + 15, Blocks.COBBLESTONE, 0);
		ComponentHumanStrongholdStructure.setBlock(world, i + 1, j + 10, k + 16, Blocks.COBBLESTONE, 0);
		ComponentHumanStrongholdStructure.setBlock(world, i + 1, j + 11, k + 0, Blocks.STONEBRICK, 2);
		ComponentHumanStrongholdStructure.setBlock(world, i + 1, j + 11, k + 16, Blocks.STONEBRICK, 2);
		ComponentHumanStrongholdStructure.setBlock(world, i + 2, j + 0, k + 0, Blocks.STONE, 0);
		ComponentHumanStrongholdStructure.setBlock(world, i + 2, j + 0, k + 1, Blocks.STONE, 0);
		ComponentHumanStrongholdStructure.setBlock(world, i + 2, j + 0, k + 2, Blocks.STONE, 0);
		ComponentHumanStrongholdStructure.setBlock(world, i + 2, j + 0, k + 3, Blocks.STONE, 0);
		ComponentHumanStrongholdStructure.setBlock(world, i + 2, j + 0, k + 4, Blocks.STONE, 0);
		ComponentHumanStrongholdStructure.setBlock(world, i + 2, j + 0, k + 5, Blocks.STONE, 0);
		ComponentHumanStrongholdStructure.setBlock(world, i + 2, j + 0, k + 6, Blocks.STONE, 0);
		ComponentHumanStrongholdStructure.setBlock(world, i + 2, j + 0, k + 7, Blocks.COBBLESTONE, 0);
		ComponentHumanStrongholdStructure.setBlock(world, i + 2, j + 0, k + 8, Blocks.COBBLESTONE, 0);
		ComponentHumanStrongholdStructure.setBlock(world, i + 2, j + 0, k + 9, Blocks.COBBLESTONE, 0);
		ComponentHumanStrongholdStructure.setBlock(world, i + 2, j + 0, k + 10, Blocks.COBBLESTONE, 0);
		ComponentHumanStrongholdStructure.setBlock(world, i + 2, j + 0, k + 11, Blocks.MOSSY_COBBLESTONE, 0);
		ComponentHumanStrongholdStructure.setBlock(world, i + 2, j + 0, k + 12, Blocks.COBBLESTONE, 0);
		ComponentHumanStrongholdStructure.setBlock(world, i + 2, j + 0, k + 13, Blocks.COBBLESTONE, 0);
		ComponentHumanStrongholdStructure.setBlock(world, i + 2, j + 0, k + 14, Blocks.COBBLESTONE, 0);
		ComponentHumanStrongholdStructure.setBlock(world, i + 2, j + 0, k + 15, Blocks.COBBLESTONE, 0);
		ComponentHumanStrongholdStructure.setBlock(world, i + 2, j + 0, k + 16, Blocks.STONE, 0);
		ComponentHumanStrongholdStructure.setBlock(world, i + 2, j + 1, k + 0, Blocks.COBBLESTONE, 0);
		ComponentHumanStrongholdStructure.setBlock(world, i + 2, j + 1, k + 1, Blocks.STONEBRICK, 2);
		ComponentHumanStrongholdStructure.setBlock(world, i + 2, j + 1, k + 7, Blocks.STONEBRICK, 0);
		ComponentHumanStrongholdStructure.setBlock(world, i + 2, j + 1, k + 11, Blocks.STONE_BRICK_STAIRS, 2);
		ComponentHumanStrongholdStructure.setBlock(world, i + 2, j + 1, k + 16, Blocks.COBBLESTONE, 0);
		ComponentHumanStrongholdStructure.setBlock(world, i + 2, j + 2, k + 0, Blocks.MOSSY_COBBLESTONE, 0);
		ComponentHumanStrongholdStructure.setBlock(world, i + 2, j + 2, k + 1, Blocks.STONEBRICK, 0);
		ComponentHumanStrongholdStructure.setBlock(world, i + 2, j + 2, k + 2, Blocks.COBBLESTONE, 0);
		ComponentHumanStrongholdStructure.setBlock(world, i + 2, j + 2, k + 3, Blocks.STONEBRICK, 2);
		ComponentHumanStrongholdStructure.setBlock(world, i + 2, j + 2, k + 4, Blocks.STONEBRICK, 0);
		ComponentHumanStrongholdStructure.setBlock(world, i + 2, j + 2, k + 5, Blocks.STONEBRICK, 0);
		ComponentHumanStrongholdStructure.setBlock(world, i + 2, j + 2, k + 6, Blocks.STONEBRICK, 0);
		ComponentHumanStrongholdStructure.setBlock(world, i + 2, j + 2, k + 7, Blocks.STONEBRICK, 0);
		ComponentHumanStrongholdStructure.setBlock(world, i + 2, j + 2, k + 13, Blocks.STONEBRICK, 1);
		ComponentHumanStrongholdStructure.setBlock(world, i + 2, j + 2, k + 14, Blocks.MOSSY_COBBLESTONE, 0);
		ComponentHumanStrongholdStructure.setBlock(world, i + 2, j + 2, k + 16, Blocks.COBBLESTONE, 0);
		ComponentHumanStrongholdStructure.setBlock(world, i + 2, j + 3, k + 0, Blocks.MOSSY_COBBLESTONE, 0);
		ComponentHumanStrongholdStructure.setBlock(world, i + 2, j + 3, k + 1, Blocks.COBBLESTONE, 0);
		ComponentHumanStrongholdStructure.setBlock(world, i + 2, j + 3, k + 2, Blocks.STONEBRICK, 0);
		ComponentHumanStrongholdStructure.setBlock(world, i + 2, j + 3, k + 3, Blocks.MOSSY_COBBLESTONE, 0);
		ComponentHumanStrongholdStructure.setBlock(world, i + 2, j + 3, k + 4, Blocks.STONEBRICK, 0);
		ComponentHumanStrongholdStructure.setBlock(world, i + 2, j + 3, k + 5, Blocks.STONEBRICK, 0);
		ComponentHumanStrongholdStructure.setBlock(world, i + 2, j + 3, k + 6, Blocks.STONEBRICK, 0);
		ComponentHumanStrongholdStructure.setBlock(world, i + 2, j + 3, k + 7, Blocks.STONEBRICK, 2);
		ComponentHumanStrongholdStructure.setBlock(world, i + 2, j + 3, k + 8, Blocks.STONE, 0);
		ComponentHumanStrongholdStructure.setBlock(world, i + 2, j + 3, k + 12, Blocks.STONEBRICK, 0);
		ComponentHumanStrongholdStructure.setBlock(world, i + 2, j + 3, k + 13, Blocks.STONEBRICK, 2);
		ComponentHumanStrongholdStructure.setBlock(world, i + 2, j + 3, k + 16, Blocks.COBBLESTONE, 0);
		ComponentHumanStrongholdStructure.setBlock(world, i + 2, j + 4, k + 0, Blocks.COBBLESTONE, 0);
		ComponentHumanStrongholdStructure.setBlock(world, i + 2, j + 4, k + 1, Blocks.STONEBRICK, 2);
		ComponentHumanStrongholdStructure.setBlock(world, i + 2, j + 4, k + 2, Blocks.STONEBRICK, 0);
		ComponentHumanStrongholdStructure.setBlock(world, i + 2, j + 4, k + 3, Blocks.STONEBRICK, 1);
		ComponentHumanStrongholdStructure.setBlock(world, i + 2, j + 4, k + 4, Blocks.STONEBRICK, 1);
		ComponentHumanStrongholdStructure.setBlock(world, i + 2, j + 4, k + 5, Blocks.STONEBRICK, 1);
		ComponentHumanStrongholdStructure.setBlock(world, i + 2, j + 4, k + 6, Blocks.STONEBRICK, 0);
		ComponentHumanStrongholdStructure.setBlock(world, i + 2, j + 4, k + 9, Blocks.STONEBRICK, 0);
		ComponentHumanStrongholdStructure.setBlock(world, i + 2, j + 4, k + 10, Blocks.STONEBRICK, 1);
		ComponentHumanStrongholdStructure.setBlock(world, i + 2, j + 4, k + 11, Blocks.STONEBRICK, 0);
		ComponentHumanStrongholdStructure.setBlock(world, i + 2, j + 4, k + 12, Blocks.STONEBRICK, 1);
		ComponentHumanStrongholdStructure.setBlock(world, i + 2, j + 4, k + 13, Blocks.STONE, 0);
		ComponentHumanStrongholdStructure.setBlock(world, i + 2, j + 4, k + 14, Blocks.STONE, 0);
		ComponentHumanStrongholdStructure.setBlock(world, i + 2, j + 4, k + 15, Blocks.STONE, 0);
		ComponentHumanStrongholdStructure.setBlock(world, i + 2, j + 4, k + 16, Blocks.MOSSY_COBBLESTONE, 0);
		ComponentHumanStrongholdStructure.setBlock(world, i + 2, j + 5, k + 0, Blocks.MOSSY_COBBLESTONE, 0);
		ComponentHumanStrongholdStructure.setBlock(world, i + 2, j + 5, k + 9, Blocks.STONEBRICK, 1);
		ComponentHumanStrongholdStructure.setBlock(world, i + 2, j + 5, k + 12, Blocks.IRON_BARS, 0);
		ComponentHumanStrongholdStructure.setBlock(world, i + 2, j + 5, k + 13, Blocks.STONE_SLAB, 5);
		ComponentHumanStrongholdStructure.setBlock(world, i + 2, j + 5, k + 15, Blocks.STONE_SLAB, 5);
		ComponentHumanStrongholdStructure.setBlock(world, i + 2, j + 5, k + 16, Blocks.COBBLESTONE, 0);
		ComponentHumanStrongholdStructure.setBlock(world, i + 2, j + 6, k + 0, Blocks.COBBLESTONE, 0);
		ComponentHumanStrongholdStructure.setBlock(world, i + 2, j + 6, k + 8, Blocks.STONE_BRICK_STAIRS, 6);
		ComponentHumanStrongholdStructure.setBlock(world, i + 2, j + 6, k + 9, Blocks.STONEBRICK, 0);
		ComponentHumanStrongholdStructure.setBlock(world, i + 2, j + 6, k + 12, Blocks.IRON_BARS, 0);
		ComponentHumanStrongholdStructure.setBlock(world, i + 2, j + 6, k + 16, Blocks.MOSSY_COBBLESTONE, 0);
		ComponentHumanStrongholdStructure.setBlock(world, i + 2, j + 7, k + 0, Blocks.COBBLESTONE, 0);
		ComponentHumanStrongholdStructure.setBlock(world, i + 2, j + 7, k + 8, Blocks.COBBLESTONE, 0);
		ComponentHumanStrongholdStructure.setBlock(world, i + 2, j + 7, k + 10, Blocks.STONEBRICK, 1);
		ComponentHumanStrongholdStructure.setBlock(world, i + 2, j + 7, k + 11, Blocks.STONEBRICK, 0);
		ComponentHumanStrongholdStructure.setBlock(world, i + 2, j + 7, k + 12, Blocks.STONEBRICK, 0);
		ComponentHumanStrongholdStructure.setBlock(world, i + 2, j + 7, k + 13, Blocks.STONEBRICK, 2);
		ComponentHumanStrongholdStructure.setBlock(world, i + 2, j + 7, k + 15, Blocks.STONEBRICK, 2);
		ComponentHumanStrongholdStructure.setBlock(world, i + 2, j + 7, k + 16, Blocks.COBBLESTONE, 0);
		ComponentHumanStrongholdStructure.setBlock(world, i + 2, j + 8, k + 0, Blocks.COBBLESTONE, 0);
		ComponentHumanStrongholdStructure.setBlock(world, i + 2, j + 8, k + 7, Blocks.STONEBRICK, 0);
		ComponentHumanStrongholdStructure.setBlock(world, i + 2, j + 8, k + 12, Blocks.IRON_BARS, 0);
		ComponentHumanStrongholdStructure.setBlock(world, i + 2, j + 8, k + 16, Blocks.MOSSY_COBBLESTONE, 0);
		ComponentHumanStrongholdStructure.setBlock(world, i + 2, j + 9, k + 0, Blocks.COBBLESTONE, 0);
		ComponentHumanStrongholdStructure.setBlock(world, i + 2, j + 9, k + 7, Blocks.MOSSY_COBBLESTONE, 0);
		ComponentHumanStrongholdStructure.setBlock(world, i + 2, j + 9, k + 12, Blocks.IRON_BARS, 0);
		ComponentHumanStrongholdStructure.setBlock(world, i + 2, j + 9, k + 16, Blocks.COBBLESTONE, 0);
		ComponentHumanStrongholdStructure.setBlock(world, i + 2, j + 10, k + 0, Blocks.COBBLESTONE, 0);
		ComponentHumanStrongholdStructure.setBlock(world, i + 2, j + 10, k + 1, Blocks.COBBLESTONE, 0);
		ComponentHumanStrongholdStructure.setBlock(world, i + 2, j + 10, k + 2, Blocks.COBBLESTONE, 0);
		ComponentHumanStrongholdStructure.setBlock(world, i + 2, j + 10, k + 3, Blocks.COBBLESTONE, 0);
		ComponentHumanStrongholdStructure.setBlock(world, i + 2, j + 10, k + 4, Blocks.COBBLESTONE, 0);
		ComponentHumanStrongholdStructure.setBlock(world, i + 2, j + 10, k + 5, Blocks.COBBLESTONE, 0);
		ComponentHumanStrongholdStructure.setBlock(world, i + 2, j + 10, k + 6, Blocks.COBBLESTONE, 0);
		ComponentHumanStrongholdStructure.setBlock(world, i + 2, j + 10, k + 7, Blocks.COBBLESTONE, 0);
		ComponentHumanStrongholdStructure.setBlock(world, i + 2, j + 10, k + 8, Blocks.COBBLESTONE, 0);
		ComponentHumanStrongholdStructure.setBlock(world, i + 2, j + 10, k + 9, Blocks.COBBLESTONE, 0);
		ComponentHumanStrongholdStructure.setBlock(world, i + 2, j + 10, k + 10, Blocks.COBBLESTONE, 0);
		ComponentHumanStrongholdStructure.setBlock(world, i + 2, j + 10, k + 11, Blocks.MOSSY_COBBLESTONE, 0);
		ComponentHumanStrongholdStructure.setBlock(world, i + 2, j + 10, k + 12, Blocks.COBBLESTONE, 0);
		ComponentHumanStrongholdStructure.setBlock(world, i + 2, j + 10, k + 13, Blocks.MOSSY_COBBLESTONE, 0);
		ComponentHumanStrongholdStructure.setBlock(world, i + 2, j + 10, k + 14, Blocks.COBBLESTONE, 0);
		ComponentHumanStrongholdStructure.setBlock(world, i + 2, j + 10, k + 15, Blocks.COBBLESTONE, 0);
		ComponentHumanStrongholdStructure.setBlock(world, i + 2, j + 10, k + 16, Blocks.COBBLESTONE, 0);
		ComponentHumanStrongholdStructure.setBlock(world, i + 2, j + 11, k + 0, Blocks.STONEBRICK, 2);
		ComponentHumanStrongholdStructure.setBlock(world, i + 2, j + 11, k + 16, Blocks.STONEBRICK, 1);
		ComponentHumanStrongholdStructure.setBlock(world, i + 3, j + 0, k + 0, Blocks.STONE, 0);
		ComponentHumanStrongholdStructure.setBlock(world, i + 3, j + 0, k + 1, Blocks.COBBLESTONE, 0);
		ComponentHumanStrongholdStructure.setBlock(world, i + 3, j + 0, k + 2, Blocks.STONE, 0);
		ComponentHumanStrongholdStructure.setBlock(world, i + 3, j + 0, k + 3, Blocks.STONE, 0);
		ComponentHumanStrongholdStructure.setBlock(world, i + 3, j + 0, k + 4, Blocks.STONE, 0);
		ComponentHumanStrongholdStructure.setBlock(world, i + 3, j + 0, k + 5, Blocks.STONE, 0);
		ComponentHumanStrongholdStructure.setBlock(world, i + 3, j + 0, k + 6, Blocks.STONE, 0);
		ComponentHumanStrongholdStructure.setBlock(world, i + 3, j + 0, k + 7, Blocks.STONE, 0);
		ComponentHumanStrongholdStructure.setBlock(world, i + 3, j + 0, k + 8, Blocks.STONE, 0);
		ComponentHumanStrongholdStructure.setBlock(world, i + 3, j + 0, k + 9, Blocks.COBBLESTONE, 0);
		ComponentHumanStrongholdStructure.setBlock(world, i + 3, j + 0, k + 10, Blocks.MOSSY_COBBLESTONE, 0);
		ComponentHumanStrongholdStructure.setBlock(world, i + 3, j + 0, k + 11, Blocks.COBBLESTONE, 0);
		ComponentHumanStrongholdStructure.setBlock(world, i + 3, j + 0, k + 12, Blocks.MOSSY_COBBLESTONE, 0);
		ComponentHumanStrongholdStructure.setBlock(world, i + 3, j + 0, k + 13, Blocks.MOSSY_COBBLESTONE, 0);
		ComponentHumanStrongholdStructure.setBlock(world, i + 3, j + 0, k + 14, Blocks.COBBLESTONE, 0);
		ComponentHumanStrongholdStructure.setBlock(world, i + 3, j + 0, k + 15, Blocks.COBBLESTONE, 0);
		ComponentHumanStrongholdStructure.setBlock(world, i + 3, j + 0, k + 16, Blocks.STONE, 0);
		ComponentHumanStrongholdStructure.setBlock(world, i + 3, j + 1, k + 0, Blocks.COBBLESTONE, 0);
		ComponentHumanStrongholdStructure.setBlock(world, i + 3, j + 1, k + 1, Blocks.STONE_BRICK_STAIRS, 3);
		ComponentHumanStrongholdStructure.setBlock(world, i + 3, j + 1, k + 12, Blocks.STONEBRICK, 2);
		ComponentHumanStrongholdStructure.setBlock(world, i + 3, j + 1, k + 13, Blocks.STONEBRICK, 1);
		ComponentHumanStrongholdStructure.setBlock(world, i + 3, j + 1, k + 16, Blocks.COBBLESTONE, 0);
		ComponentHumanStrongholdStructure.setBlock(world, i + 3, j + 2, k + 0, Blocks.COBBLESTONE, 0);
		ComponentHumanStrongholdStructure.setBlock(world, i + 3, j + 2, k + 12, Blocks.STONEBRICK, 1);
		ComponentHumanStrongholdStructure.setBlock(world, i + 3, j + 2, k + 13, Blocks.STONEBRICK, 1);
		ComponentHumanStrongholdStructure.setBlock(world, i + 3, j + 2, k + 14, Blocks.STONEBRICK, 2);
		ComponentHumanStrongholdStructure.setBlock(world, i + 3, j + 2, k + 16, Blocks.COBBLESTONE, 0);
		ComponentHumanStrongholdStructure.setBlock(world, i + 3, j + 3, k + 0, Blocks.COBBLESTONE, 0);
		ComponentHumanStrongholdStructure.setBlock(world, i + 3, j + 3, k + 1, Blocks.STONEBRICK, 2);
		ComponentHumanStrongholdStructure.setBlock(world, i + 3, j + 3, k + 7, Blocks.STONEBRICK, 1);
		ComponentHumanStrongholdStructure.setBlock(world, i + 3, j + 3, k + 8, Blocks.STONE, 0);
		ComponentHumanStrongholdStructure.setBlock(world, i + 3, j + 3, k + 12, Blocks.STONEBRICK, 2);
		ComponentHumanStrongholdStructure.setBlock(world, i + 3, j + 3, k + 13, Blocks.STONEBRICK, 0);
		ComponentHumanStrongholdStructure.setBlock(world, i + 3, j + 3, k + 16, Blocks.COBBLESTONE, 0);
		ComponentHumanStrongholdStructure.setBlock(world, i + 3, j + 4, k + 0, Blocks.COBBLESTONE, 0);
		ComponentHumanStrongholdStructure.setBlock(world, i + 3, j + 4, k + 3, Blocks.COBBLESTONE, 0);
		ComponentHumanStrongholdStructure.setBlock(world, i + 3, j + 4, k + 4, Blocks.MOSSY_COBBLESTONE, 0);
		ComponentHumanStrongholdStructure.setBlock(world, i + 3, j + 4, k + 5, Blocks.STONEBRICK, 0);
		ComponentHumanStrongholdStructure.setBlock(world, i + 3, j + 4, k + 6, Blocks.MOSSY_COBBLESTONE, 0);
		ComponentHumanStrongholdStructure.setBlock(world, i + 3, j + 4, k + 9, Blocks.STONEBRICK, 0);
		ComponentHumanStrongholdStructure.setBlock(world, i + 3, j + 4, k + 10, Blocks.STONEBRICK, 2);
		ComponentHumanStrongholdStructure.setBlock(world, i + 3, j + 4, k + 11, Blocks.STONEBRICK, 1);
		ComponentHumanStrongholdStructure.setBlock(world, i + 3, j + 4, k + 12, Blocks.STONEBRICK, 1);
		ComponentHumanStrongholdStructure.setBlock(world, i + 3, j + 4, k + 13, Blocks.STONEBRICK, 0);
		ComponentHumanStrongholdStructure.setBlock(world, i + 3, j + 4, k + 14, Blocks.STONEBRICK, 2);
		ComponentHumanStrongholdStructure.setBlock(world, i + 3, j + 4, k + 15, Blocks.STONEBRICK, 2);
		ComponentHumanStrongholdStructure.setBlock(world, i + 3, j + 4, k + 16, Blocks.COBBLESTONE, 0);
		ComponentHumanStrongholdStructure.setBlock(world, i + 3, j + 5, k + 0, Blocks.COBBLESTONE, 0);
		ComponentHumanStrongholdStructure.setBlock(world, i + 3, j + 5, k + 9, Blocks.STONEBRICK, 0);
		ComponentHumanStrongholdStructure.setBlock(world, i + 3, j + 5, k + 12, Blocks.IRON_BARS, 0);
		ComponentHumanStrongholdStructure.setBlock(world, i + 3, j + 5, k + 16, Blocks.COBBLESTONE, 0);
		ComponentHumanStrongholdStructure.setBlock(world, i + 3, j + 6, k + 0, Blocks.COBBLESTONE, 0);
		ComponentHumanStrongholdStructure.setBlock(world, i + 3, j + 6, k + 8, Blocks.STONE_BRICK_STAIRS, 6);
		ComponentHumanStrongholdStructure.setBlock(world, i + 3, j + 6, k + 9, Blocks.STONEBRICK, 2);
		ComponentHumanStrongholdStructure.setBlock(world, i + 3, j + 6, k + 12, Blocks.IRON_BARS, 0);
		ComponentHumanStrongholdStructure.setBlock(world, i + 3, j + 6, k + 16, Blocks.MOSSY_COBBLESTONE, 0);
		ComponentHumanStrongholdStructure.setBlock(world, i + 3, j + 7, k + 0, Blocks.MOSSY_COBBLESTONE, 0);
		ComponentHumanStrongholdStructure.setBlock(world, i + 3, j + 7, k + 8, Blocks.STONEBRICK, 2);
		ComponentHumanStrongholdStructure.setBlock(world, i + 3, j + 7, k + 9, Blocks.MOSSY_COBBLESTONE, 0);
		ComponentHumanStrongholdStructure.setBlock(world, i + 3, j + 7, k + 10, Blocks.MOSSY_COBBLESTONE, 0);
		ComponentHumanStrongholdStructure.setBlock(world, i + 3, j + 7, k + 11, Blocks.STONEBRICK, 0);
		ComponentHumanStrongholdStructure.setBlock(world, i + 3, j + 7, k + 12, Blocks.STONEBRICK, 0);
		ComponentHumanStrongholdStructure.setBlock(world, i + 3, j + 7, k + 13, Blocks.STONEBRICK, 2);
		ComponentHumanStrongholdStructure.setBlock(world, i + 3, j + 7, k + 14, Blocks.STONEBRICK, 0);
		ComponentHumanStrongholdStructure.setBlock(world, i + 3, j + 7, k + 15, Blocks.STONEBRICK, 0);
		ComponentHumanStrongholdStructure.setBlock(world, i + 3, j + 7, k + 16, Blocks.COBBLESTONE, 0);
		ComponentHumanStrongholdStructure.setBlock(world, i + 3, j + 8, k + 0, Blocks.COBBLESTONE, 0);
		ComponentHumanStrongholdStructure.setBlock(world, i + 3, j + 8, k + 7, Blocks.STONE_BRICK_STAIRS, 6);
		ComponentHumanStrongholdStructure.setBlock(world, i + 3, j + 8, k + 8, Blocks.STONEBRICK, 2);
		ComponentHumanStrongholdStructure.setBlock(world, i + 3, j + 8, k + 9, Blocks.IRON_BARS, 0);
		ComponentHumanStrongholdStructure.setBlock(world, i + 3, j + 8, k + 10, Blocks.IRON_BARS, 0);
		ComponentHumanStrongholdStructure.setBlock(world, i + 3, j + 8, k + 12, Blocks.STONEBRICK, 2);
		ComponentHumanStrongholdStructure.setBlock(world, i + 3, j + 8, k + 13, Blocks.IRON_BARS, 0);
		ComponentHumanStrongholdStructure.setBlock(world, i + 3, j + 8, k + 14, Blocks.IRON_BARS, 0);
		ComponentHumanStrongholdStructure.setBlock(world, i + 3, j + 8, k + 15, Blocks.STONEBRICK, 0);
		ComponentHumanStrongholdStructure.setBlock(world, i + 3, j + 8, k + 16, Blocks.MOSSY_COBBLESTONE, 0);
		ComponentHumanStrongholdStructure.setBlock(world, i + 3, j + 9, k + 0, Blocks.COBBLESTONE, 0);
		ComponentHumanStrongholdStructure.setBlock(world, i + 3, j + 9, k + 7, Blocks.STONEBRICK, 1);
		ComponentHumanStrongholdStructure.setBlock(world, i + 3, j + 9, k + 8, Blocks.IRON_BARS, 0);
		ComponentHumanStrongholdStructure.setBlock(world, i + 3, j + 9, k + 9, Blocks.IRON_BARS, 0);
		ComponentHumanStrongholdStructure.setBlock(world, i + 3, j + 9, k + 12, Blocks.STONEBRICK, 1);
		ComponentHumanStrongholdStructure.setBlock(world, i + 3, j + 9, k + 13, Blocks.IRON_BARS, 0);
		ComponentHumanStrongholdStructure.setBlock(world, i + 3, j + 9, k + 14, Blocks.IRON_BARS, 0);
		ComponentHumanStrongholdStructure.setBlock(world, i + 3, j + 9, k + 15, Blocks.STONEBRICK, 0);
		ComponentHumanStrongholdStructure.setBlock(world, i + 3, j + 9, k + 16, Blocks.COBBLESTONE, 0);
		ComponentHumanStrongholdStructure.setBlock(world, i + 3, j + 10, k + 0, Blocks.COBBLESTONE, 0);
		ComponentHumanStrongholdStructure.setBlock(world, i + 3, j + 10, k + 1, Blocks.COBBLESTONE, 0);
		ComponentHumanStrongholdStructure.setBlock(world, i + 3, j + 10, k + 2, Blocks.COBBLESTONE, 0);
		ComponentHumanStrongholdStructure.setBlock(world, i + 3, j + 10, k + 3, Blocks.COBBLESTONE, 0);
		ComponentHumanStrongholdStructure.setBlock(world, i + 3, j + 10, k + 4, Blocks.MOSSY_COBBLESTONE, 0);
		ComponentHumanStrongholdStructure.setBlock(world, i + 3, j + 10, k + 5, Blocks.COBBLESTONE, 0);
		ComponentHumanStrongholdStructure.setBlock(world, i + 3, j + 10, k + 6, Blocks.COBBLESTONE, 0);
		ComponentHumanStrongholdStructure.setBlock(world, i + 3, j + 10, k + 7, Blocks.COBBLESTONE, 0);
		ComponentHumanStrongholdStructure.setBlock(world, i + 3, j + 10, k + 8, Blocks.MOSSY_COBBLESTONE, 0);
		ComponentHumanStrongholdStructure.setBlock(world, i + 3, j + 10, k + 9, Blocks.COBBLESTONE, 0);
		ComponentHumanStrongholdStructure.setBlock(world, i + 3, j + 10, k + 10, Blocks.COBBLESTONE, 0);
		ComponentHumanStrongholdStructure.setBlock(world, i + 3, j + 10, k + 11, Blocks.COBBLESTONE, 0);
		ComponentHumanStrongholdStructure.setBlock(world, i + 3, j + 10, k + 12, Blocks.COBBLESTONE, 0);
		ComponentHumanStrongholdStructure.setBlock(world, i + 3, j + 10, k + 13, Blocks.COBBLESTONE, 0);
		ComponentHumanStrongholdStructure.setBlock(world, i + 3, j + 10, k + 14, Blocks.COBBLESTONE, 0);
		ComponentHumanStrongholdStructure.setBlock(world, i + 3, j + 10, k + 15, Blocks.COBBLESTONE, 0);
		ComponentHumanStrongholdStructure.setBlock(world, i + 3, j + 10, k + 16, Blocks.COBBLESTONE, 0);
		ComponentHumanStrongholdStructure.setBlock(world, i + 4, j + 0, k + 0, Blocks.STONE, 0);
		ComponentHumanStrongholdStructure.setBlock(world, i + 4, j + 0, k + 1, Blocks.COBBLESTONE, 0);
		ComponentHumanStrongholdStructure.setBlock(world, i + 4, j + 0, k + 2, Blocks.COBBLESTONE, 0);
		ComponentHumanStrongholdStructure.setBlock(world, i + 4, j + 0, k + 3, Blocks.STONE, 0);
		ComponentHumanStrongholdStructure.setBlock(world, i + 4, j + 0, k + 4, Blocks.STONE, 0);
		ComponentHumanStrongholdStructure.setBlock(world, i + 4, j + 0, k + 5, Blocks.STONE, 0);
		ComponentHumanStrongholdStructure.setBlock(world, i + 4, j + 0, k + 6, Blocks.STONE, 0);
		ComponentHumanStrongholdStructure.setBlock(world, i + 4, j + 0, k + 7, Blocks.STONE, 0);
		ComponentHumanStrongholdStructure.setBlock(world, i + 4, j + 0, k + 8, Blocks.STONE, 0);
		ComponentHumanStrongholdStructure.setBlock(world, i + 4, j + 0, k + 9, Blocks.COBBLESTONE, 0);
		ComponentHumanStrongholdStructure.setBlock(world, i + 4, j + 0, k + 10, Blocks.COBBLESTONE, 0);
		ComponentHumanStrongholdStructure.setBlock(world, i + 4, j + 0, k + 11, Blocks.COBBLESTONE, 0);
		ComponentHumanStrongholdStructure.setBlock(world, i + 4, j + 0, k + 12, Blocks.COBBLESTONE, 0);
		ComponentHumanStrongholdStructure.setBlock(world, i + 4, j + 0, k + 13, Blocks.MOSSY_COBBLESTONE, 0);
		ComponentHumanStrongholdStructure.setBlock(world, i + 4, j + 0, k + 14, Blocks.COBBLESTONE, 0);
		ComponentHumanStrongholdStructure.setBlock(world, i + 4, j + 0, k + 15, Blocks.COBBLESTONE, 0);
		ComponentHumanStrongholdStructure.setBlock(world, i + 4, j + 0, k + 16, Blocks.STONE, 0);
		ComponentHumanStrongholdStructure.setBlock(world, i + 4, j + 1, k + 0, Blocks.MOSSY_COBBLESTONE, 0);
		ComponentHumanStrongholdStructure.setBlock(world, i + 4, j + 1, k + 1, Blocks.STONEBRICK, 0);
		ComponentHumanStrongholdStructure.setBlock(world, i + 4, j + 1, k + 2, Blocks.STONEBRICK, 2);
		ComponentHumanStrongholdStructure.setBlock(world, i + 4, j + 1, k + 12, Blocks.STONEBRICK, 1);
		ComponentHumanStrongholdStructure.setBlock(world, i + 4, j + 1, k + 13, Blocks.STONEBRICK, 2);
		ComponentHumanStrongholdStructure.setBlock(world, i + 4, j + 1, k + 16, Blocks.COBBLESTONE, 0);
		ComponentHumanStrongholdStructure.setBlock(world, i + 4, j + 2, k + 0, Blocks.COBBLESTONE, 0);
		ComponentHumanStrongholdStructure.setBlock(world, i + 4, j + 2, k + 1, Blocks.STONEBRICK, 2);
		ComponentHumanStrongholdStructure.setBlock(world, i + 4, j + 2, k + 12, Blocks.STONEBRICK, 1);
		ComponentHumanStrongholdStructure.setBlock(world, i + 4, j + 2, k + 13, Blocks.STONEBRICK, 2);
		ComponentHumanStrongholdStructure.setBlock(world, i + 4, j + 2, k + 14, Blocks.STONEBRICK, 1);
		ComponentHumanStrongholdStructure.setBlock(world, i + 4, j + 2, k + 16, Blocks.COBBLESTONE, 0);
		ComponentHumanStrongholdStructure.setBlock(world, i + 4, j + 3, k + 0, Blocks.MOSSY_COBBLESTONE, 0);
		ComponentHumanStrongholdStructure.setBlock(world, i + 4, j + 3, k + 7, Blocks.STONEBRICK, 0);
		ComponentHumanStrongholdStructure.setBlock(world, i + 4, j + 3, k + 8, Blocks.STONEBRICK, 0);
		ComponentHumanStrongholdStructure.setBlock(world, i + 4, j + 3, k + 12, Blocks.STONEBRICK, 0);
		ComponentHumanStrongholdStructure.setBlock(world, i + 4, j + 3, k + 13, Blocks.STONEBRICK, 2);
		ComponentHumanStrongholdStructure.setBlock(world, i + 4, j + 3, k + 16, Blocks.COBBLESTONE, 0);
		ComponentHumanStrongholdStructure.setBlock(world, i + 4, j + 4, k + 0, Blocks.COBBLESTONE, 0);
		ComponentHumanStrongholdStructure.setBlock(world, i + 4, j + 4, k + 3, Blocks.STONEBRICK, 0);
		ComponentHumanStrongholdStructure.setBlock(world, i + 4, j + 4, k + 4, Blocks.BEDROCK, 0);
		ComponentHumanStrongholdStructure.setBlock(world, i + 4, j + 4, k + 5, Blocks.BEDROCK, 0);
		ComponentHumanStrongholdStructure.setBlock(world, i + 4, j + 4, k + 6, Blocks.BEDROCK, 0);
		ComponentHumanStrongholdStructure.setBlock(world, i + 4, j + 4, k + 7, Blocks.BEDROCK, 0);
		ComponentHumanStrongholdStructure.setBlock(world, i + 4, j + 4, k + 8, Blocks.BEDROCK, 0);
		ComponentHumanStrongholdStructure.setBlock(world, i + 4, j + 4, k + 9, Blocks.STONEBRICK, 2);
		ComponentHumanStrongholdStructure.setBlock(world, i + 4, j + 4, k + 10, Blocks.STONEBRICK, 0);
		ComponentHumanStrongholdStructure.setBlock(world, i + 4, j + 4, k + 11, Blocks.STONEBRICK, 0);
		ComponentHumanStrongholdStructure.setBlock(world, i + 4, j + 4, k + 12, Blocks.MOSSY_COBBLESTONE, 0);
		ComponentHumanStrongholdStructure.setBlock(world, i + 4, j + 4, k + 13, Blocks.COBBLESTONE, 0);
		ComponentHumanStrongholdStructure.setBlock(world, i + 4, j + 4, k + 14, Blocks.COBBLESTONE, 0);
		ComponentHumanStrongholdStructure.setBlock(world, i + 4, j + 4, k + 15, Blocks.STONEBRICK, 1);
		ComponentHumanStrongholdStructure.setBlock(world, i + 4, j + 4, k + 16, Blocks.COBBLESTONE, 0);
		ComponentHumanStrongholdStructure.setBlock(world, i + 4, j + 5, k + 0, Blocks.MOSSY_COBBLESTONE, 0);
		ComponentHumanStrongholdStructure.setBlock(world, i + 4, j + 5, k + 3, Blocks.STONEBRICK, 2);
		ComponentHumanStrongholdStructure.setBlock(world, i + 4, j + 5, k + 4, Blocks.BEDROCK, 0);
		ComponentHumanStrongholdStructure.setBlock(world, i + 4, j + 5, k + 5, Blocks.BEDROCK, 0);
		ComponentHumanStrongholdStructure.setBlock(world, i + 4, j + 5, k + 7, Blocks.BEDROCK, 0);
		ComponentHumanStrongholdStructure.setBlock(world, i + 4, j + 5, k + 8, Blocks.BEDROCK, 0);
		ComponentHumanStrongholdStructure.setBlock(world, i + 4, j + 5, k + 9, Blocks.STONEBRICK, 1);
		ComponentHumanStrongholdStructure.setBlock(world, i + 4, j + 5, k + 12, Blocks.STONEBRICK, 0);
		ComponentHumanStrongholdStructure.setBlock(world, i + 4, j + 5, k + 13, Blocks.STONEBRICK, 1);
		ComponentHumanStrongholdStructure.setBlock(world, i + 4, j + 5, k + 14, Blocks.MOSSY_COBBLESTONE, 0);
		ComponentHumanStrongholdStructure.setBlock(world, i + 4, j + 5, k + 15, Blocks.STONE_BRICK_STAIRS, 2);
		ComponentHumanStrongholdStructure.setBlock(world, i + 4, j + 5, k + 16, Blocks.COBBLESTONE, 0);
		ComponentHumanStrongholdStructure.setBlock(world, i + 4, j + 6, k + 0, Blocks.COBBLESTONE, 0);
		ComponentHumanStrongholdStructure.setBlock(world, i + 4, j + 6, k + 3, Blocks.STONEBRICK, 2);
		ComponentHumanStrongholdStructure.setBlock(world, i + 4, j + 6, k + 4, Blocks.BEDROCK, 0);
		ComponentHumanStrongholdStructure.setBlock(world, i + 4, j + 6, k + 5, Blocks.BEDROCK, 0);
		ComponentHumanStrongholdStructure.setBlock(world, i + 4, j + 6, k + 7, Blocks.BEDROCK, 0);
		ComponentHumanStrongholdStructure.setBlock(world, i + 4, j + 6, k + 8, Blocks.BEDROCK, 0);
		ComponentHumanStrongholdStructure.setBlock(world, i + 4, j + 6, k + 9, Blocks.STONEBRICK, 2);
		ComponentHumanStrongholdStructure.setBlock(world, i + 4, j + 6, k + 12, Blocks.MOSSY_COBBLESTONE, 0);
		ComponentHumanStrongholdStructure.setBlock(world, i + 4, j + 6, k + 13, Blocks.STONEBRICK, 2);
		world.setBlockState(new BlockPos(i + 4, j + 6, k + 14), Blocks.DISPENSER.getDefaultState());
		this.generateADispenser(world, structureBoundingBoxIn, rand, i + 4, j + 6, k + 14);
		world.getBlockState(new BlockPos(i + 4, j + 6, k + 14)).getBlock().rotateBlock(world, new BlockPos(i + 4, j + 6, k + 14), EnumFacing.WEST);
		world.getBlockState(new BlockPos(i + 4, j + 6, k + 14)).getBlock().rotateBlock(world, new BlockPos(i + 4, j + 6, k + 14), EnumFacing.WEST);
		ComponentHumanStrongholdStructure.setBlock(world, i + 4, j + 6, k + 15, Blocks.MOSSY_COBBLESTONE, 0);
		ComponentHumanStrongholdStructure.setBlock(world, i + 4, j + 6, k + 16, Blocks.COBBLESTONE, 0);
		ComponentHumanStrongholdStructure.setBlock(world, i + 4, j + 7, k + 0, Blocks.MOSSY_COBBLESTONE, 0);
		ComponentHumanStrongholdStructure.setBlock(world, i + 4, j + 7, k + 3, Blocks.STONEBRICK, 2);
		ComponentHumanStrongholdStructure.setBlock(world, i + 4, j + 7, k + 4, Blocks.BEDROCK, 0);
		ComponentHumanStrongholdStructure.setBlock(world, i + 4, j + 7, k + 5, Blocks.BEDROCK, 0);
		ComponentHumanStrongholdStructure.setBlock(world, i + 4, j + 7, k + 6, Blocks.BEDROCK, 0);
		ComponentHumanStrongholdStructure.setBlock(world, i + 4, j + 7, k + 7, Blocks.BEDROCK, 0);
		ComponentHumanStrongholdStructure.setBlock(world, i + 4, j + 7, k + 8, Blocks.STONEBRICK, 0);
		ComponentHumanStrongholdStructure.setBlock(world, i + 4, j + 7, k + 9, Blocks.STONEBRICK, 1);
		ComponentHumanStrongholdStructure.setBlock(world, i + 4, j + 7, k + 10, Blocks.STONE_BRICK_STAIRS, 0);
		ComponentHumanStrongholdStructure.setBlock(world, i + 4, j + 7, k + 11, Blocks.STONE_BRICK_STAIRS, 6);
		ComponentHumanStrongholdStructure.setBlock(world, i + 4, j + 7, k + 12, Blocks.COBBLESTONE, 0);
		ComponentHumanStrongholdStructure.setBlock(world, i + 4, j + 7, k + 13, Blocks.STONEBRICK, 0);
		ComponentHumanStrongholdStructure.setBlock(world, i + 4, j + 7, k + 14, Blocks.STONEBRICK, 0);
		ComponentHumanStrongholdStructure.setBlock(world, i + 4, j + 7, k + 15, Blocks.STONEBRICK, 1);
		ComponentHumanStrongholdStructure.setBlock(world, i + 4, j + 7, k + 16, Blocks.MOSSY_COBBLESTONE, 0);
		ComponentHumanStrongholdStructure.setBlock(world, i + 4, j + 8, k + 0, Blocks.COBBLESTONE, 0);
		ComponentHumanStrongholdStructure.setBlock(world, i + 4, j + 8, k + 3, Blocks.STONE_BRICK_STAIRS, 2);
		ComponentHumanStrongholdStructure.setBlock(world, i + 4, j + 8, k + 4, Blocks.STONE_BRICK_STAIRS, 0);
		ComponentHumanStrongholdStructure.setBlock(world, i + 4, j + 8, k + 5, Blocks.MOSSY_COBBLESTONE, 0);
		ComponentHumanStrongholdStructure.setBlock(world, i + 4, j + 8, k + 6, Blocks.MOSSY_COBBLESTONE, 0);
		ComponentHumanStrongholdStructure.setBlock(world, i + 4, j + 8, k + 7, Blocks.MOSSY_COBBLESTONE, 0);
		ComponentHumanStrongholdStructure.setBlock(world, i + 4, j + 8, k + 15, Blocks.STONEBRICK, 2);
		ComponentHumanStrongholdStructure.setBlock(world, i + 4, j + 8, k + 16, Blocks.MOSSY_COBBLESTONE, 0);
		ComponentHumanStrongholdStructure.setBlock(world, i + 4, j + 9, k + 0, Blocks.MOSSY_COBBLESTONE, 0);
		ComponentHumanStrongholdStructure.setBlock(world, i + 4, j + 9, k + 3, Blocks.STONEBRICK, 1);
		ComponentHumanStrongholdStructure.setBlock(world, i + 4, j + 9, k + 4, Blocks.STONEBRICK, 1);
		ComponentHumanStrongholdStructure.setBlock(world, i + 4, j + 9, k + 5, Blocks.STONEBRICK, 1);
		ComponentHumanStrongholdStructure.setBlock(world, i + 4, j + 9, k + 6, Blocks.STONEBRICK, 2);
		ComponentHumanStrongholdStructure.setBlock(world, i + 4, j + 9, k + 7, Blocks.COBBLESTONE, 0);
		ComponentHumanStrongholdStructure.setBlock(world, i + 4, j + 9, k + 16, Blocks.COBBLESTONE, 0);
		ComponentHumanStrongholdStructure.setBlock(world, i + 4, j + 10, k + 0, Blocks.COBBLESTONE, 0);
		ComponentHumanStrongholdStructure.setBlock(world, i + 4, j + 10, k + 1, Blocks.COBBLESTONE, 0);
		ComponentHumanStrongholdStructure.setBlock(world, i + 4, j + 10, k + 2, Blocks.COBBLESTONE, 0);
		ComponentHumanStrongholdStructure.setBlock(world, i + 4, j + 10, k + 3, Blocks.COBBLESTONE, 0);
		ComponentHumanStrongholdStructure.setBlock(world, i + 4, j + 10, k + 4, Blocks.COBBLESTONE, 0);
		ComponentHumanStrongholdStructure.setBlock(world, i + 4, j + 10, k + 5, Blocks.COBBLESTONE, 0);
		ComponentHumanStrongholdStructure.setBlock(world, i + 4, j + 10, k + 6, Blocks.COBBLESTONE, 0);
		ComponentHumanStrongholdStructure.setBlock(world, i + 4, j + 10, k + 7, Blocks.COBBLESTONE, 0);
		ComponentHumanStrongholdStructure.setBlock(world, i + 4, j + 10, k + 8, Blocks.MOSSY_COBBLESTONE, 0);
		ComponentHumanStrongholdStructure.setBlock(world, i + 4, j + 10, k + 9, Blocks.COBBLESTONE, 0);
		ComponentHumanStrongholdStructure.setBlock(world, i + 4, j + 10, k + 10, Blocks.MOSSY_COBBLESTONE, 0);
		ComponentHumanStrongholdStructure.setBlock(world, i + 4, j + 10, k + 11, Blocks.COBBLESTONE, 0);
		ComponentHumanStrongholdStructure.setBlock(world, i + 4, j + 10, k + 12, Blocks.MOSSY_COBBLESTONE, 0);
		ComponentHumanStrongholdStructure.setBlock(world, i + 4, j + 10, k + 13, Blocks.COBBLESTONE, 0);
		ComponentHumanStrongholdStructure.setBlock(world, i + 4, j + 10, k + 14, Blocks.COBBLESTONE, 0);
		ComponentHumanStrongholdStructure.setBlock(world, i + 4, j + 10, k + 15, Blocks.COBBLESTONE, 0);
		ComponentHumanStrongholdStructure.setBlock(world, i + 4, j + 10, k + 16, Blocks.COBBLESTONE, 0);
		ComponentHumanStrongholdStructure.setBlock(world, i + 4, j + 11, k + 16, Blocks.STONEBRICK, 0);
		ComponentHumanStrongholdStructure.setBlock(world, i + 4, j + 12, k + 16, Blocks.STONEBRICK, 0);
		ComponentHumanStrongholdStructure.setBlock(world, i + 5, j + 0, k + 0, Blocks.STONE, 0);
		ComponentHumanStrongholdStructure.setBlock(world, i + 5, j + 0, k + 1, Blocks.COBBLESTONE, 0);
		ComponentHumanStrongholdStructure.setBlock(world, i + 5, j + 0, k + 2, Blocks.STONE, 0);
		ComponentHumanStrongholdStructure.setBlock(world, i + 5, j + 0, k + 3, Blocks.STONE, 0);
		ComponentHumanStrongholdStructure.setBlock(world, i + 5, j + 0, k + 4, Blocks.STONE, 0);
		ComponentHumanStrongholdStructure.setBlock(world, i + 5, j + 0, k + 5, Blocks.STONE, 0);
		ComponentHumanStrongholdStructure.setBlock(world, i + 5, j + 0, k + 6, Blocks.STONE, 0);
		ComponentHumanStrongholdStructure.setBlock(world, i + 5, j + 0, k + 7, Blocks.COBBLESTONE, 0);
		ComponentHumanStrongholdStructure.setBlock(world, i + 5, j + 0, k + 8, Blocks.STONE, 0);
		ComponentHumanStrongholdStructure.setBlock(world, i + 5, j + 0, k + 9, Blocks.COBBLESTONE, 0);
		ComponentHumanStrongholdStructure.setBlock(world, i + 5, j + 0, k + 10, Blocks.COBBLESTONE, 0);
		ComponentHumanStrongholdStructure.setBlock(world, i + 5, j + 0, k + 11, Blocks.COBBLESTONE, 0);
		ComponentHumanStrongholdStructure.setBlock(world, i + 5, j + 0, k + 12, Blocks.COBBLESTONE, 0);
		ComponentHumanStrongholdStructure.setBlock(world, i + 5, j + 0, k + 13, Blocks.COBBLESTONE, 0);
		ComponentHumanStrongholdStructure.setBlock(world, i + 5, j + 0, k + 14, Blocks.COBBLESTONE, 0);
		ComponentHumanStrongholdStructure.setBlock(world, i + 5, j + 0, k + 15, Blocks.COBBLESTONE, 0);
		ComponentHumanStrongholdStructure.setBlock(world, i + 5, j + 0, k + 16, Blocks.STONE, 0);
		ComponentHumanStrongholdStructure.setBlock(world, i + 5, j + 1, k + 0, Blocks.COBBLESTONE, 0);
		ComponentHumanStrongholdStructure.setBlock(world, i + 5, j + 1, k + 1, Blocks.STONEBRICK, 1);
		ComponentHumanStrongholdStructure.setBlock(world, i + 5, j + 1, k + 7, Blocks.STONEBRICK, 2);
		ComponentHumanStrongholdStructure.setBlock(world, i + 5, j + 1, k + 11, Blocks.STONE_BRICK_STAIRS, 2);
		ComponentHumanStrongholdStructure.setBlock(world, i + 5, j + 1, k + 16, Blocks.COBBLESTONE, 0);
		ComponentHumanStrongholdStructure.setBlock(world, i + 5, j + 2, k + 0, Blocks.COBBLESTONE, 0);
		ComponentHumanStrongholdStructure.setBlock(world, i + 5, j + 2, k + 7, Blocks.STONEBRICK, 1);
		ComponentHumanStrongholdStructure.setBlock(world, i + 5, j + 2, k + 13, Blocks.STONEBRICK, 2);
		ComponentHumanStrongholdStructure.setBlock(world, i + 5, j + 2, k + 14, Blocks.STONEBRICK, 2);
		ComponentHumanStrongholdStructure.setBlock(world, i + 5, j + 2, k + 16, Blocks.COBBLESTONE, 0);
		ComponentHumanStrongholdStructure.setBlock(world, i + 5, j + 3, k + 0, Blocks.COBBLESTONE, 0);
		ComponentHumanStrongholdStructure.setBlock(world, i + 5, j + 3, k + 7, Blocks.STONEBRICK, 0);
		ComponentHumanStrongholdStructure.setBlock(world, i + 5, j + 3, k + 8, Blocks.STONEBRICK, 0);
		ComponentHumanStrongholdStructure.setBlock(world, i + 5, j + 3, k + 12, Blocks.STONEBRICK, 0);
		ComponentHumanStrongholdStructure.setBlock(world, i + 5, j + 3, k + 16, Blocks.COBBLESTONE, 0);
		ComponentHumanStrongholdStructure.setBlock(world, i + 5, j + 4, k + 0, Blocks.COBBLESTONE, 0);
		ComponentHumanStrongholdStructure.setBlock(world, i + 5, j + 4, k + 3, Blocks.STONEBRICK, 2);
		ComponentHumanStrongholdStructure.setBlock(world, i + 5, j + 4, k + 4, Blocks.BEDROCK, 0);
		ComponentHumanStrongholdStructure.setBlock(world, i + 5, j + 4, k + 5, Blocks.BEDROCK, 0);
		ComponentHumanStrongholdStructure.setBlock(world, i + 5, j + 4, k + 6, Blocks.BEDROCK, 0);
		ComponentHumanStrongholdStructure.setBlock(world, i + 5, j + 4, k + 7, Blocks.BEDROCK, 0);
		ComponentHumanStrongholdStructure.setBlock(world, i + 5, j + 4, k + 8, Blocks.BEDROCK, 0);
		ComponentHumanStrongholdStructure.setBlock(world, i + 5, j + 4, k + 9, Blocks.STONE_BRICK_STAIRS, 5);
		ComponentHumanStrongholdStructure.setBlock(world, i + 5, j + 4, k + 10, Blocks.STONEBRICK, 1);
		ComponentHumanStrongholdStructure.setBlock(world, i + 5, j + 4, k + 11, Blocks.STONEBRICK, 2);
		ComponentHumanStrongholdStructure.setBlock(world, i + 5, j + 4, k + 12, Blocks.STONEBRICK, 2);
		ComponentHumanStrongholdStructure.setBlock(world, i + 5, j + 4, k + 16, Blocks.MOSSY_COBBLESTONE, 0);
		ComponentHumanStrongholdStructure.setBlock(world, i + 5, j + 5, k + 0, Blocks.COBBLESTONE, 0);
		ComponentHumanStrongholdStructure.setBlock(world, i + 5, j + 5, k + 3, Blocks.STONEBRICK, 2);
		ComponentHumanStrongholdStructure.setBlock(world, i + 5, j + 5, k + 4, Blocks.BEDROCK, 0);
		ComponentHumanStrongholdStructure.setBlock(world, i + 5, j + 5, k + 8, Blocks.BEDROCK, 0);
		ComponentHumanStrongholdStructure.setBlock(world, i + 5, j + 5, k + 9, Blocks.STONEBRICK, 0);
		ComponentHumanStrongholdStructure.setBlock(world, i + 5, j + 5, k + 12, Blocks.STONE_BRICK_STAIRS, 1);
		ComponentHumanStrongholdStructure.setBlock(world, i + 5, j + 5, k + 13, Blocks.STONEBRICK, 2);
		ComponentHumanStrongholdStructure.setBlock(world, i + 5, j + 5, k + 14, Blocks.STONEBRICK, 1);
		ComponentHumanStrongholdStructure.setBlock(world, i + 5, j + 5, k + 16, Blocks.COBBLESTONE, 0);
		ComponentHumanStrongholdStructure.setBlock(world, i + 5, j + 6, k + 0, Blocks.MOSSY_COBBLESTONE, 0);
		ComponentHumanStrongholdStructure.setBlock(world, i + 5, j + 6, k + 3, Blocks.STONEBRICK, 1);
		ComponentHumanStrongholdStructure.setBlock(world, i + 5, j + 6, k + 4, Blocks.BEDROCK, 0);
		ComponentHumanStrongholdStructure.setBlock(world, i + 5, j + 6, k + 8, Blocks.BEDROCK, 0);
		ComponentHumanStrongholdStructure.setBlock(world, i + 5, j + 6, k + 9, Blocks.STONEBRICK, 0);
		ComponentHumanStrongholdStructure.setBlock(world, i + 5, j + 6, k + 12, Blocks.STONEBRICK, 1);
		ComponentHumanStrongholdStructure.setBlock(world, i + 5, j + 6, k + 13, Blocks.STONEBRICK, 0);
		ComponentHumanStrongholdStructure.setBlock(world, i + 5, j + 6, k + 16, Blocks.MOSSY_COBBLESTONE, 0);
		ComponentHumanStrongholdStructure.setBlock(world, i + 5, j + 7, k + 0, Blocks.COBBLESTONE, 0);
		ComponentHumanStrongholdStructure.setBlock(world, i + 5, j + 7, k + 3, Blocks.STONEBRICK, 2);
		ComponentHumanStrongholdStructure.setBlock(world, i + 5, j + 7, k + 4, Blocks.BEDROCK, 0);
		ComponentHumanStrongholdStructure.setBlock(world, i + 5, j + 7, k + 5, Blocks.BEDROCK, 0);
		ComponentHumanStrongholdStructure.setBlock(world, i + 5, j + 7, k + 6, Blocks.BEDROCK, 0);
		ComponentHumanStrongholdStructure.setBlock(world, i + 5, j + 7, k + 7, Blocks.BEDROCK, 0);
		ComponentHumanStrongholdStructure.setBlock(world, i + 5, j + 7, k + 8, Blocks.BEDROCK, 0);
		ComponentHumanStrongholdStructure.setBlock(world, i + 5, j + 7, k + 9, Blocks.STONEBRICK, 1);
		ComponentHumanStrongholdStructure.setBlock(world, i + 5, j + 7, k + 10, Blocks.STONEBRICK, 0);
		ComponentHumanStrongholdStructure.setBlock(world, i + 5, j + 7, k + 11, Blocks.STONEBRICK, 1);
		ComponentHumanStrongholdStructure.setBlock(world, i + 5, j + 7, k + 12, Blocks.STONEBRICK, 2);
		ComponentHumanStrongholdStructure.setBlock(world, i + 5, j + 7, k + 13, Blocks.STONEBRICK, 1);
		ComponentHumanStrongholdStructure.setBlock(world, i + 5, j + 7, k + 14, Blocks.STONE_BRICK_STAIRS, 6);
		ComponentHumanStrongholdStructure.setBlock(world, i + 5, j + 7, k + 16, Blocks.COBBLESTONE, 0);
		ComponentHumanStrongholdStructure.setBlock(world, i + 5, j + 8, k + 0, Blocks.COBBLESTONE, 0);
		ComponentHumanStrongholdStructure.setBlock(world, i + 5, j + 8, k + 3, Blocks.MOSSY_COBBLESTONE, 0);
		ComponentHumanStrongholdStructure.setBlock(world, i + 5, j + 8, k + 7, Blocks.COBBLESTONE, 0);
		ComponentHumanStrongholdStructure.setBlock(world, i + 5, j + 8, k + 8, Blocks.MOSSY_COBBLESTONE, 0);
		ComponentHumanStrongholdStructure.setBlock(world, i + 5, j + 8, k + 9, Blocks.STONEBRICK, 2);
		ComponentHumanStrongholdStructure.setBlock(world, i + 5, j + 8, k + 14, Blocks.STONE, 0);
		ComponentHumanStrongholdStructure.setBlock(world, i + 5, j + 8, k + 16, Blocks.COBBLESTONE, 0);
		ComponentHumanStrongholdStructure.setBlock(world, i + 5, j + 9, k + 0, Blocks.COBBLESTONE, 0);
		ComponentHumanStrongholdStructure.setBlock(world, i + 5, j + 9, k + 3, Blocks.STONEBRICK, 2);
		ComponentHumanStrongholdStructure.setBlock(world, i + 5, j + 9, k + 7, Blocks.STONEBRICK, 0);
		ComponentHumanStrongholdStructure.setBlock(world, i + 5, j + 9, k + 8, Blocks.STONEBRICK, 1);
		ComponentHumanStrongholdStructure.setBlock(world, i + 5, j + 9, k + 9, Blocks.STONEBRICK, 0);
		ComponentHumanStrongholdStructure.setBlock(world, i + 5, j + 9, k + 16, Blocks.COBBLESTONE, 0);
		ComponentHumanStrongholdStructure.setBlock(world, i + 5, j + 10, k + 0, Blocks.COBBLESTONE, 0);
		ComponentHumanStrongholdStructure.setBlock(world, i + 5, j + 10, k + 1, Blocks.COBBLESTONE, 0);
		ComponentHumanStrongholdStructure.setBlock(world, i + 5, j + 10, k + 2, Blocks.COBBLESTONE, 0);
		ComponentHumanStrongholdStructure.setBlock(world, i + 5, j + 10, k + 3, Blocks.MOSSY_COBBLESTONE, 0);
		ComponentHumanStrongholdStructure.setBlock(world, i + 5, j + 10, k + 4, Blocks.COBBLESTONE, 0);
		ComponentHumanStrongholdStructure.setBlock(world, i + 5, j + 10, k + 5, Blocks.COBBLESTONE, 0);
		ComponentHumanStrongholdStructure.setBlock(world, i + 5, j + 10, k + 6, Blocks.COBBLESTONE, 0);
		ComponentHumanStrongholdStructure.setBlock(world, i + 5, j + 10, k + 7, Blocks.COBBLESTONE, 0);
		ComponentHumanStrongholdStructure.setBlock(world, i + 5, j + 10, k + 8, Blocks.COBBLESTONE, 0);
		ComponentHumanStrongholdStructure.setBlock(world, i + 5, j + 10, k + 9, Blocks.COBBLESTONE, 0);
		ComponentHumanStrongholdStructure.setBlock(world, i + 5, j + 10, k + 10, Blocks.COBBLESTONE, 0);
		ComponentHumanStrongholdStructure.setBlock(world, i + 5, j + 10, k + 11, Blocks.COBBLESTONE, 0);
		ComponentHumanStrongholdStructure.setBlock(world, i + 5, j + 10, k + 12, Blocks.MOSSY_COBBLESTONE, 0);
		ComponentHumanStrongholdStructure.setBlock(world, i + 5, j + 10, k + 13, Blocks.COBBLESTONE, 0);
		ComponentHumanStrongholdStructure.setBlock(world, i + 5, j + 10, k + 14, Blocks.MOSSY_COBBLESTONE, 0);
		ComponentHumanStrongholdStructure.setBlock(world, i + 5, j + 10, k + 15, Blocks.COBBLESTONE, 0);
		ComponentHumanStrongholdStructure.setBlock(world, i + 5, j + 10, k + 16, Blocks.COBBLESTONE, 0);
		ComponentHumanStrongholdStructure.setBlock(world, i + 5, j + 11, k + 0, Blocks.STONEBRICK, 2);
		ComponentHumanStrongholdStructure.setBlock(world, i + 5, j + 11, k + 16, Blocks.STONEBRICK, 2);
		ComponentHumanStrongholdStructure.setBlock(world, i + 6, j + 0, k + 0, Blocks.STONE, 0);
		ComponentHumanStrongholdStructure.setBlock(world, i + 6, j + 0, k + 1, Blocks.COBBLESTONE, 0);
		ComponentHumanStrongholdStructure.setBlock(world, i + 6, j + 0, k + 2, Blocks.COBBLESTONE, 0);
		ComponentHumanStrongholdStructure.setBlock(world, i + 6, j + 0, k + 3, Blocks.STONE, 0);
		ComponentHumanStrongholdStructure.setBlock(world, i + 6, j + 0, k + 4, Blocks.STONE, 0);
		ComponentHumanStrongholdStructure.setBlock(world, i + 6, j + 0, k + 5, Blocks.STONE, 0);
		ComponentHumanStrongholdStructure.setBlock(world, i + 6, j + 0, k + 6, Blocks.STONE, 0);
		ComponentHumanStrongholdStructure.setBlock(world, i + 6, j + 0, k + 7, Blocks.COBBLESTONE, 0);
		ComponentHumanStrongholdStructure.setBlock(world, i + 6, j + 0, k + 8, Blocks.COBBLESTONE, 0);
		ComponentHumanStrongholdStructure.setBlock(world, i + 6, j + 0, k + 9, Blocks.COBBLESTONE, 0);
		ComponentHumanStrongholdStructure.setBlock(world, i + 6, j + 0, k + 10, Blocks.COBBLESTONE, 0);
		ComponentHumanStrongholdStructure.setBlock(world, i + 6, j + 0, k + 11, Blocks.MOSSY_COBBLESTONE, 0);
		ComponentHumanStrongholdStructure.setBlock(world, i + 6, j + 0, k + 12, Blocks.COBBLESTONE, 0);
		ComponentHumanStrongholdStructure.setBlock(world, i + 6, j + 0, k + 13, Blocks.COBBLESTONE, 0);
		ComponentHumanStrongholdStructure.setBlock(world, i + 6, j + 0, k + 14, Blocks.COBBLESTONE, 0);
		ComponentHumanStrongholdStructure.setBlock(world, i + 6, j + 0, k + 15, Blocks.COBBLESTONE, 0);
		ComponentHumanStrongholdStructure.setBlock(world, i + 6, j + 0, k + 16, Blocks.STONE, 0);
		ComponentHumanStrongholdStructure.setBlock(world, i + 6, j + 1, k + 0, Blocks.COBBLESTONE, 0);
		ComponentHumanStrongholdStructure.setBlock(world, i + 6, j + 1, k + 1, Blocks.STONEBRICK, 2);
		ComponentHumanStrongholdStructure.setBlock(world, i + 6, j + 1, k + 2, Blocks.STONEBRICK, 1);
		ComponentHumanStrongholdStructure.setBlock(world, i + 6, j + 1, k + 7, Blocks.STONEBRICK, 0);
		ComponentHumanStrongholdStructure.setBlock(world, i + 6, j + 1, k + 10, Blocks.STONEBRICK, 2);
		ComponentHumanStrongholdStructure.setBlock(world, i + 6, j + 1, k + 11, Blocks.STONEBRICK, 1);
		ComponentHumanStrongholdStructure.setBlock(world, i + 6, j + 1, k + 12, Blocks.STONEBRICK, 1);
		ComponentHumanStrongholdStructure.setBlock(world, i + 6, j + 1, k + 13, Blocks.STONEBRICK, 2);
		ComponentHumanStrongholdStructure.setBlock(world, i + 6, j + 1, k + 14, Blocks.STONEBRICK, 2);
		ComponentHumanStrongholdStructure.setBlock(world, i + 6, j + 1, k + 15, Blocks.STONEBRICK, 2);
		ComponentHumanStrongholdStructure.setBlock(world, i + 6, j + 1, k + 16, Blocks.COBBLESTONE, 0);
		ComponentHumanStrongholdStructure.setBlock(world, i + 6, j + 2, k + 0, Blocks.COBBLESTONE, 0);
		ComponentHumanStrongholdStructure.setBlock(world, i + 6, j + 2, k + 7, Blocks.STONEBRICK, 1);
		ComponentHumanStrongholdStructure.setBlock(world, i + 6, j + 2, k + 10, Blocks.STONEBRICK, 0);
		ComponentHumanStrongholdStructure.setBlock(world, i + 6, j + 2, k + 11, Blocks.STONEBRICK, 2);
		ComponentHumanStrongholdStructure.setBlock(world, i + 6, j + 2, k + 12, Blocks.STONEBRICK, 2);
		ComponentHumanStrongholdStructure.setBlock(world, i + 6, j + 2, k + 13, Blocks.STONEBRICK, 0);
		ComponentHumanStrongholdStructure.setBlock(world, i + 6, j + 2, k + 16, Blocks.COBBLESTONE, 0);
		ComponentHumanStrongholdStructure.setBlock(world, i + 6, j + 3, k + 0, Blocks.MOSSY_COBBLESTONE, 0);
		ComponentHumanStrongholdStructure.setBlock(world, i + 6, j + 3, k + 7, Blocks.STONE_BRICK_STAIRS, 1);
		ComponentHumanStrongholdStructure.setBlock(world, i + 6, j + 3, k + 8, Blocks.STONEBRICK, 2);
		ComponentHumanStrongholdStructure.setBlock(world, i + 6, j + 3, k + 9, Blocks.STONEBRICK, 2);
		ComponentHumanStrongholdStructure.setBlock(world, i + 6, j + 3, k + 10, Blocks.STONEBRICK, 1);
		ComponentHumanStrongholdStructure.setBlock(world, i + 6, j + 3, k + 11, Blocks.STONEBRICK, 0);
		ComponentHumanStrongholdStructure.setBlock(world, i + 6, j + 3, k + 12, Blocks.STONEBRICK, 2);
		ComponentHumanStrongholdStructure.setBlock(world, i + 6, j + 3, k + 13, Blocks.STONEBRICK, 0);
		ComponentHumanStrongholdStructure.setBlock(world, i + 6, j + 3, k + 14, Blocks.STONEBRICK, 1);
		ComponentHumanStrongholdStructure.setBlock(world, i + 6, j + 3, k + 15, Blocks.STONEBRICK, 2);
		ComponentHumanStrongholdStructure.setBlock(world, i + 6, j + 3, k + 16, Blocks.MOSSY_COBBLESTONE, 0);
		ComponentHumanStrongholdStructure.setBlock(world, i + 6, j + 4, k + 0, Blocks.COBBLESTONE, 0);
		ComponentHumanStrongholdStructure.setBlock(world, i + 6, j + 4, k + 3, Blocks.STONEBRICK, 0);
		ComponentHumanStrongholdStructure.setBlock(world, i + 6, j + 4, k + 4, Blocks.BEDROCK, 0);
		ComponentHumanStrongholdStructure.setBlock(world, i + 6, j + 4, k + 5, Blocks.BEDROCK, 0);
		ComponentHumanStrongholdStructure.setBlock(world, i + 6, j + 4, k + 6, Blocks.BEDROCK, 0);
		ComponentHumanStrongholdStructure.setBlock(world, i + 6, j + 4, k + 7, Blocks.BEDROCK, 0);
		ComponentHumanStrongholdStructure.setBlock(world, i + 6, j + 4, k + 8, Blocks.BEDROCK, 0);
		ComponentHumanStrongholdStructure.setBlock(world, i + 6, j + 4, k + 9, Blocks.STONEBRICK, 2);
		ComponentHumanStrongholdStructure.setBlock(world, i + 6, j + 4, k + 10, Blocks.STONEBRICK, 0);
		ComponentHumanStrongholdStructure.setBlock(world, i + 6, j + 4, k + 11, Blocks.STONEBRICK, 1);
		ComponentHumanStrongholdStructure.setBlock(world, i + 6, j + 4, k + 12, Blocks.STONEBRICK, 2);
		ComponentHumanStrongholdStructure.setBlock(world, i + 6, j + 4, k + 14, Blocks.STONEBRICK, 0);
		ComponentHumanStrongholdStructure.setBlock(world, i + 6, j + 4, k + 16, Blocks.MOSSY_COBBLESTONE, 0);
		ComponentHumanStrongholdStructure.setBlock(world, i + 6, j + 5, k + 0, Blocks.MOSSY_COBBLESTONE, 0);
		ComponentHumanStrongholdStructure.setBlock(world, i + 6, j + 5, k + 3, Blocks.STONEBRICK, 2);
		ComponentHumanStrongholdStructure.setBlock(world, i + 6, j + 5, k + 4, Blocks.BEDROCK, 0);
		ComponentHumanStrongholdStructure.setBlock(world, i + 6, j + 5, k + 6, Blocks.AIR, 4);
		ComponentHumanStrongholdStructure.setBlock(world, i + 6, j + 5, k + 8, Blocks.BEDROCK, 0);
		ComponentHumanStrongholdStructure.setBlock(world, i + 6, j + 5, k + 9, Blocks.STONE, 0);
		ComponentHumanStrongholdStructure.setBlock(world, i + 6, j + 5, k + 12, Blocks.STONE_BRICK_STAIRS, 2);
		ComponentHumanStrongholdStructure.setBlock(world, i + 6, j + 5, k + 15, Blocks.STONEBRICK, 1);
		ComponentHumanStrongholdStructure.setBlock(world, i + 6, j + 5, k + 16, Blocks.COBBLESTONE, 0);
		ComponentHumanStrongholdStructure.setBlock(world, i + 6, j + 6, k + 0, Blocks.COBBLESTONE, 0);
		ComponentHumanStrongholdStructure.setBlock(world, i + 6, j + 6, k + 3, Blocks.STONEBRICK, 1);
		ComponentHumanStrongholdStructure.setBlock(world, i + 6, j + 6, k + 4, Blocks.BEDROCK, 0);
		ComponentHumanStrongholdStructure.setBlock(world, i + 6, j + 6, k + 8, Blocks.BEDROCK, 0);
		ComponentHumanStrongholdStructure.setBlock(world, i + 6, j + 6, k + 9, Blocks.STONEBRICK, 2);
		ComponentHumanStrongholdStructure.setBlock(world, i + 6, j + 6, k + 12, Blocks.STONEBRICK, 1);
		ComponentHumanStrongholdStructure.setBlock(world, i + 6, j + 6, k + 13, Blocks.STONEBRICK, 2);
		ComponentHumanStrongholdStructure.setBlock(world, i + 6, j + 6, k + 15, Blocks.STONEBRICK, 1);
		ComponentHumanStrongholdStructure.setBlock(world, i + 6, j + 6, k + 16, Blocks.COBBLESTONE, 0);
		ComponentHumanStrongholdStructure.setBlock(world, i + 6, j + 7, k + 0, Blocks.COBBLESTONE, 0);
		ComponentHumanStrongholdStructure.setBlock(world, i + 6, j + 7, k + 3, Blocks.STONEBRICK, 1);
		ComponentHumanStrongholdStructure.setBlock(world, i + 6, j + 7, k + 4, Blocks.BEDROCK, 0);
		ComponentHumanStrongholdStructure.setBlock(world, i + 6, j + 7, k + 5, Blocks.BEDROCK, 0);
		ComponentHumanStrongholdStructure.setBlock(world, i + 6, j + 7, k + 6, Blocks.BEDROCK, 0);
		ComponentHumanStrongholdStructure.setBlock(world, i + 6, j + 7, k + 7, Blocks.BEDROCK, 0);
		ComponentHumanStrongholdStructure.setBlock(world, i + 6, j + 7, k + 8, Blocks.BEDROCK, 0);
		ComponentHumanStrongholdStructure.setBlock(world, i + 6, j + 7, k + 9, Blocks.STONEBRICK, 1);
		ComponentHumanStrongholdStructure.setBlock(world, i + 6, j + 7, k + 10, Blocks.STONEBRICK, 2);
		ComponentHumanStrongholdStructure.setBlock(world, i + 6, j + 7, k + 12, Blocks.STONEBRICK, 2);
		ComponentHumanStrongholdStructure.setBlock(world, i + 6, j + 7, k + 13, Blocks.STONEBRICK, 0);
		ComponentHumanStrongholdStructure.setBlock(world, i + 6, j + 7, k + 14, Blocks.STONEBRICK, 0);
		ComponentHumanStrongholdStructure.setBlock(world, i + 6, j + 7, k + 15, Blocks.STONEBRICK, 1);
		ComponentHumanStrongholdStructure.setBlock(world, i + 6, j + 7, k + 16, Blocks.COBBLESTONE, 0);
		ComponentHumanStrongholdStructure.setBlock(world, i + 6, j + 8, k + 0, Blocks.COBBLESTONE, 0);
		ComponentHumanStrongholdStructure.setBlock(world, i + 6, j + 8, k + 3, Blocks.STONEBRICK, 1);
		ComponentHumanStrongholdStructure.setBlock(world, i + 6, j + 8, k + 9, Blocks.STONEBRICK, 2);
		ComponentHumanStrongholdStructure.setBlock(world, i + 6, j + 8, k + 15, Blocks.STONEBRICK, 0);
		ComponentHumanStrongholdStructure.setBlock(world, i + 6, j + 8, k + 16, Blocks.MOSSY_COBBLESTONE, 0);
		ComponentHumanStrongholdStructure.setBlock(world, i + 6, j + 9, k + 0, Blocks.COBBLESTONE, 0);
		ComponentHumanStrongholdStructure.setBlock(world, i + 6, j + 9, k + 3, Blocks.STONEBRICK, 2);
		ComponentHumanStrongholdStructure.setBlock(world, i + 6, j + 9, k + 9, Blocks.STONEBRICK, 1);
		ComponentHumanStrongholdStructure.setBlock(world, i + 6, j + 9, k + 16, Blocks.COBBLESTONE, 0);
		ComponentHumanStrongholdStructure.setBlock(world, i + 6, j + 10, k + 0, Blocks.COBBLESTONE, 0);
		ComponentHumanStrongholdStructure.setBlock(world, i + 6, j + 10, k + 1, Blocks.COBBLESTONE, 0);
		ComponentHumanStrongholdStructure.setBlock(world, i + 6, j + 10, k + 2, Blocks.COBBLESTONE, 0);
		ComponentHumanStrongholdStructure.setBlock(world, i + 6, j + 10, k + 3, Blocks.COBBLESTONE, 0);
		ComponentHumanStrongholdStructure.setBlock(world, i + 6, j + 10, k + 4, Blocks.COBBLESTONE, 0);
		ComponentHumanStrongholdStructure.setBlock(world, i + 6, j + 10, k + 5, Blocks.COBBLESTONE, 0);
		ComponentHumanStrongholdStructure.setBlock(world, i + 6, j + 10, k + 6, Blocks.COBBLESTONE, 0);
		ComponentHumanStrongholdStructure.setBlock(world, i + 6, j + 10, k + 7, Blocks.COBBLESTONE, 0);
		ComponentHumanStrongholdStructure.setBlock(world, i + 6, j + 10, k + 8, Blocks.COBBLESTONE, 0);
		ComponentHumanStrongholdStructure.setBlock(world, i + 6, j + 10, k + 9, Blocks.COBBLESTONE, 0);
		ComponentHumanStrongholdStructure.setBlock(world, i + 6, j + 10, k + 10, Blocks.COBBLESTONE, 0);
		ComponentHumanStrongholdStructure.setBlock(world, i + 6, j + 10, k + 11, Blocks.MOSSY_COBBLESTONE, 0);
		ComponentHumanStrongholdStructure.setBlock(world, i + 6, j + 10, k + 12, Blocks.COBBLESTONE, 0);
		ComponentHumanStrongholdStructure.setBlock(world, i + 6, j + 10, k + 13, Blocks.COBBLESTONE, 0);
		ComponentHumanStrongholdStructure.setBlock(world, i + 6, j + 10, k + 14, Blocks.COBBLESTONE, 0);
		ComponentHumanStrongholdStructure.setBlock(world, i + 6, j + 10, k + 15, Blocks.COBBLESTONE, 0);
		ComponentHumanStrongholdStructure.setBlock(world, i + 6, j + 10, k + 16, Blocks.COBBLESTONE, 0);
		ComponentHumanStrongholdStructure.setBlock(world, i + 7, j + 0, k + 0, Blocks.STONE, 0);
		ComponentHumanStrongholdStructure.setBlock(world, i + 7, j + 0, k + 1, Blocks.COBBLESTONE, 0);
		ComponentHumanStrongholdStructure.setBlock(world, i + 7, j + 0, k + 2, Blocks.COBBLESTONE, 0);
		ComponentHumanStrongholdStructure.setBlock(world, i + 7, j + 0, k + 3, Blocks.COBBLESTONE, 0);
		ComponentHumanStrongholdStructure.setBlock(world, i + 7, j + 0, k + 4, Blocks.COBBLESTONE, 0);
		ComponentHumanStrongholdStructure.setBlock(world, i + 7, j + 0, k + 5, Blocks.COBBLESTONE, 0);
		ComponentHumanStrongholdStructure.setBlock(world, i + 7, j + 0, k + 6, Blocks.COBBLESTONE, 0);
		ComponentHumanStrongholdStructure.setBlock(world, i + 7, j + 0, k + 7, Blocks.COBBLESTONE, 0);
		ComponentHumanStrongholdStructure.setBlock(world, i + 7, j + 0, k + 8, Blocks.COBBLESTONE, 0);
		ComponentHumanStrongholdStructure.setBlock(world, i + 7, j + 0, k + 9, Blocks.MOSSY_COBBLESTONE, 0);
		ComponentHumanStrongholdStructure.setBlock(world, i + 7, j + 0, k + 10, Blocks.COBBLESTONE, 0);
		ComponentHumanStrongholdStructure.setBlock(world, i + 7, j + 0, k + 11, Blocks.COBBLESTONE, 0);
		ComponentHumanStrongholdStructure.setBlock(world, i + 7, j + 0, k + 12, Blocks.COBBLESTONE, 0);
		ComponentHumanStrongholdStructure.setBlock(world, i + 7, j + 0, k + 13, Blocks.COBBLESTONE, 0);
		ComponentHumanStrongholdStructure.setBlock(world, i + 7, j + 0, k + 14, Blocks.COBBLESTONE, 0);
		ComponentHumanStrongholdStructure.setBlock(world, i + 7, j + 0, k + 15, Blocks.COBBLESTONE, 0);
		ComponentHumanStrongholdStructure.setBlock(world, i + 7, j + 0, k + 16, Blocks.STONE, 0);
		ComponentHumanStrongholdStructure.setBlock(world, i + 7, j + 1, k + 0, Blocks.COBBLESTONE, 0);
		ComponentHumanStrongholdStructure.setBlock(world, i + 7, j + 1, k + 1, Blocks.STONEBRICK, 2);
		ComponentHumanStrongholdStructure.setBlock(world, i + 7, j + 1, k + 2, Blocks.STONE_BRICK_STAIRS, 0);
		ComponentHumanStrongholdStructure.setBlock(world, i + 7, j + 1, k + 4, Blocks.STONEBRICK, 0);
		ComponentHumanStrongholdStructure.setBlock(world, i + 7, j + 1, k + 5, Blocks.STONE_BRICK_STAIRS, 1);
		ComponentHumanStrongholdStructure.setBlock(world, i + 7, j + 1, k + 6, Blocks.STONEBRICK, 0);
		ComponentHumanStrongholdStructure.setBlock(world, i + 7, j + 1, k + 7, Blocks.STONE_BRICK_STAIRS, 3);
		ComponentHumanStrongholdStructure.setBlock(world, i + 7, j + 1, k + 11, Blocks.STONEBRICK, 0);
		ComponentHumanStrongholdStructure.setBlock(world, i + 7, j + 1, k + 13, Blocks.STONE_BRICK_STAIRS, 1);
		ComponentHumanStrongholdStructure.setBlock(world, i + 7, j + 1, k + 14, Blocks.STONE_BRICK_STAIRS, 1);
		ComponentHumanStrongholdStructure.setBlock(world, i + 7, j + 1, k + 15, Blocks.STONE_BRICK_STAIRS, 2);
		ComponentHumanStrongholdStructure.setBlock(world, i + 7, j + 1, k + 16, Blocks.COBBLESTONE, 0);
		ComponentHumanStrongholdStructure.setBlock(world, i + 7, j + 2, k + 0, Blocks.MOSSY_COBBLESTONE, 0);
		ComponentHumanStrongholdStructure.setBlock(world, i + 7, j + 2, k + 1, Blocks.STONEBRICK, 1);
		ComponentHumanStrongholdStructure.setBlock(world, i + 7, j + 2, k + 2, Blocks.STONEBRICK, 0);
		ComponentHumanStrongholdStructure.setBlock(world, i + 7, j + 2, k + 3, Blocks.STONEBRICK, 2);
		ComponentHumanStrongholdStructure.setBlock(world, i + 7, j + 2, k + 5, Blocks.STONEBRICK, 0);
		ComponentHumanStrongholdStructure.setBlock(world, i + 7, j + 2, k + 6, Blocks.STONEBRICK, 2);
		ComponentHumanStrongholdStructure.setBlock(world, i + 7, j + 2, k + 11, Blocks.STONEBRICK, 2);
		ComponentHumanStrongholdStructure.setBlock(world, i + 7, j + 2, k + 16, Blocks.COBBLESTONE, 0);
		ComponentHumanStrongholdStructure.setBlock(world, i + 7, j + 3, k + 0, Blocks.MOSSY_COBBLESTONE, 0);
		ComponentHumanStrongholdStructure.setBlock(world, i + 7, j + 3, k + 1, Blocks.STONEBRICK, 2);
		ComponentHumanStrongholdStructure.setBlock(world, i + 7, j + 3, k + 2, Blocks.STONEBRICK, 1);
		ComponentHumanStrongholdStructure.setBlock(world, i + 7, j + 3, k + 3, Blocks.STONEBRICK, 1);
		ComponentHumanStrongholdStructure.setBlock(world, i + 7, j + 3, k + 4, Blocks.STONEBRICK, 0);
		ComponentHumanStrongholdStructure.setBlock(world, i + 7, j + 3, k + 5, Blocks.STONEBRICK, 1);
		ComponentHumanStrongholdStructure.setBlock(world, i + 7, j + 3, k + 6, Blocks.STONEBRICK, 0);
		ComponentHumanStrongholdStructure.setBlock(world, i + 7, j + 3, k + 7, Blocks.STONEBRICK, 0);
		ComponentHumanStrongholdStructure.setBlock(world, i + 7, j + 3, k + 8, Blocks.STONEBRICK, 0);
		ComponentHumanStrongholdStructure.setBlock(world, i + 7, j + 3, k + 11, Blocks.STONE_BRICK_STAIRS, 5);
		ComponentHumanStrongholdStructure.setBlock(world, i + 7, j + 3, k + 13, Blocks.STONEBRICK, 0);
		ComponentHumanStrongholdStructure.setBlock(world, i + 7, j + 3, k + 14, Blocks.STONEBRICK, 1);
		ComponentHumanStrongholdStructure.setBlock(world, i + 7, j + 3, k + 15, Blocks.STONEBRICK, 0);
		ComponentHumanStrongholdStructure.setBlock(world, i + 7, j + 3, k + 16, Blocks.COBBLESTONE, 0);
		ComponentHumanStrongholdStructure.setBlock(world, i + 7, j + 4, k + 0, Blocks.COBBLESTONE, 0);
		ComponentHumanStrongholdStructure.setBlock(world, i + 7, j + 4, k + 1, Blocks.STONEBRICK, 2);
		ComponentHumanStrongholdStructure.setBlock(world, i + 7, j + 4, k + 2, Blocks.STONEBRICK, 1);
		ComponentHumanStrongholdStructure.setBlock(world, i + 7, j + 4, k + 3, Blocks.STONEBRICK, 1);
		ComponentHumanStrongholdStructure.setBlock(world, i + 7, j + 4, k + 4, Blocks.BEDROCK, 0);
		ComponentHumanStrongholdStructure.setBlock(world, i + 7, j + 4, k + 5, Blocks.BEDROCK, 0);
		ComponentHumanStrongholdStructure.setBlock(world, i + 7, j + 4, k + 6, Blocks.BEDROCK, 0);
		ComponentHumanStrongholdStructure.setBlock(world, i + 7, j + 4, k + 7, Blocks.BEDROCK, 0);
		ComponentHumanStrongholdStructure.setBlock(world, i + 7, j + 4, k + 8, Blocks.BEDROCK, 0);
		ComponentHumanStrongholdStructure.setBlock(world, i + 7, j + 4, k + 9, Blocks.STONEBRICK, 1);
		ComponentHumanStrongholdStructure.setBlock(world, i + 7, j + 4, k + 10, Blocks.STONEBRICK, 0);
		ComponentHumanStrongholdStructure.setBlock(world, i + 7, j + 4, k + 11, Blocks.STONEBRICK, 2);
		ComponentHumanStrongholdStructure.setBlock(world, i + 7, j + 4, k + 12, Blocks.STONEBRICK, 2);
		ComponentHumanStrongholdStructure.setBlock(world, i + 7, j + 4, k + 13, Blocks.STONEBRICK, 0);
		ComponentHumanStrongholdStructure.setBlock(world, i + 7, j + 4, k + 14, Blocks.STONEBRICK, 2);
		ComponentHumanStrongholdStructure.setBlock(world, i + 7, j + 4, k + 15, Blocks.STONEBRICK, 2);
		ComponentHumanStrongholdStructure.setBlock(world, i + 7, j + 4, k + 16, Blocks.MOSSY_COBBLESTONE, 0);
		ComponentHumanStrongholdStructure.setBlock(world, i + 7, j + 5, k + 0, Blocks.COBBLESTONE, 0);
		ComponentHumanStrongholdStructure.setBlock(world, i + 7, j + 5, k + 3, Blocks.STONEBRICK, 0);
		ComponentHumanStrongholdStructure.setBlock(world, i + 7, j + 5, k + 4, Blocks.BEDROCK, 0);
		ComponentHumanStrongholdStructure.setBlock(world, i + 7, j + 5, k + 5, Blocks.BEDROCK, 0);
		ComponentHumanStrongholdStructure.setBlock(world, i + 7, j + 5, k + 6, Blocks.BEDROCK, 0);
		ComponentHumanStrongholdStructure.setBlock(world, i + 7, j + 5, k + 7, Blocks.BEDROCK, 0);
		ComponentHumanStrongholdStructure.setBlock(world, i + 7, j + 5, k + 8, Blocks.BEDROCK, 0);
		ComponentHumanStrongholdStructure.setBlock(world, i + 7, j + 5, k + 9, Blocks.STONEBRICK, 2);
		ComponentHumanStrongholdStructure.setBlock(world, i + 7, j + 5, k + 12, Blocks.STONEBRICK, 2);
		ComponentHumanStrongholdStructure.setBlock(world, i + 7, j + 5, k + 13, Blocks.STONEBRICK, 2);
		ComponentHumanStrongholdStructure.setBlock(world, i + 7, j + 5, k + 14, Blocks.STONEBRICK, 1);
		ComponentHumanStrongholdStructure.setBlock(world, i + 7, j + 5, k + 15, Blocks.STONEBRICK, 2);
		ComponentHumanStrongholdStructure.setBlock(world, i + 7, j + 5, k + 16, Blocks.COBBLESTONE, 0);
		ComponentHumanStrongholdStructure.setBlock(world, i + 7, j + 6, k + 0, Blocks.MOSSY_COBBLESTONE, 0);
		ComponentHumanStrongholdStructure.setBlock(world, i + 7, j + 6, k + 3, Blocks.STONEBRICK, 2);
		ComponentHumanStrongholdStructure.setBlock(world, i + 7, j + 6, k + 4, Blocks.BEDROCK, 0);
		ComponentHumanStrongholdStructure.setBlock(world, i + 7, j + 6, k + 5, Blocks.BEDROCK, 0);
		ComponentHumanStrongholdStructure.setBlock(world, i + 7, j + 6, k + 6, Blocks.BEDROCK, 0);
		ComponentHumanStrongholdStructure.setBlock(world, i + 7, j + 6, k + 7, Blocks.BEDROCK, 0);
		ComponentHumanStrongholdStructure.setBlock(world, i + 7, j + 6, k + 8, Blocks.BEDROCK, 0);
		ComponentHumanStrongholdStructure.setBlock(world, i + 7, j + 6, k + 9, Blocks.STONEBRICK, 0);
		ComponentHumanStrongholdStructure.setBlock(world, i + 7, j + 6, k + 12, Blocks.STONEBRICK, 0);
		ComponentHumanStrongholdStructure.setBlock(world, i + 7, j + 6, k + 13, Blocks.STONEBRICK, 0);
		ComponentHumanStrongholdStructure.setBlock(world, i + 7, j + 6, k + 14, Blocks.STONEBRICK, 0);
		ComponentHumanStrongholdStructure.setBlock(world, i + 7, j + 6, k + 15, Blocks.STONEBRICK, 1);
		ComponentHumanStrongholdStructure.setBlock(world, i + 7, j + 6, k + 16, Blocks.COBBLESTONE, 0);
		ComponentHumanStrongholdStructure.setBlock(world, i + 7, j + 7, k + 0, Blocks.COBBLESTONE, 0);
		ComponentHumanStrongholdStructure.setBlock(world, i + 7, j + 7, k + 3, Blocks.STONEBRICK, 0);
		ComponentHumanStrongholdStructure.setBlock(world, i + 7, j + 7, k + 4, Blocks.BEDROCK, 0);
		ComponentHumanStrongholdStructure.setBlock(world, i + 7, j + 7, k + 5, Blocks.BEDROCK, 0);
		ComponentHumanStrongholdStructure.setBlock(world, i + 7, j + 7, k + 6, Blocks.BEDROCK, 0);
		ComponentHumanStrongholdStructure.setBlock(world, i + 7, j + 7, k + 7, Blocks.BEDROCK, 0);
		ComponentHumanStrongholdStructure.setBlock(world, i + 7, j + 7, k + 8, Blocks.BEDROCK, 0);
		ComponentHumanStrongholdStructure.setBlock(world, i + 7, j + 7, k + 9, Blocks.STONEBRICK, 2);
		ComponentHumanStrongholdStructure.setBlock(world, i + 7, j + 7, k + 11, Blocks.MOSSY_COBBLESTONE, 0);
		ComponentHumanStrongholdStructure.setBlock(world, i + 7, j + 7, k + 12, Blocks.STONEBRICK, 2);
		ComponentHumanStrongholdStructure.setBlock(world, i + 7, j + 7, k + 13, Blocks.STONEBRICK, 2);
		ComponentHumanStrongholdStructure.setBlock(world, i + 7, j + 7, k + 14, Blocks.STONEBRICK, 2);
		ComponentHumanStrongholdStructure.setBlock(world, i + 7, j + 7, k + 15, Blocks.STONEBRICK, 2);
		ComponentHumanStrongholdStructure.setBlock(world, i + 7, j + 7, k + 16, Blocks.MOSSY_COBBLESTONE, 0);
